Workbook

Sheet 00_审核入口
A1: 00 · 审核入口
A2: 先读这一页，再看01逐品结论。蓝色为可录入区；空白=未知。冻结结论必须由更新后的证据重新生成，改单元格不等于重新批准。 | F2: 46280.89
A4: 项目 | B4: 本轮结果 | C4: 含义及限制 | D4: 建议行动
A5: 运行时间 | B5: 2026-09-15T21:21:21+08:00 | C5: 以来源自身观测日期判断新鲜度 | D5: 不可用运行时间替换历史数据日期
A6: 历史候选记录 | B6: 22 | C6: 尚待准确规格/SPU复核；不能全部视为独立已验证商品 | D6: 见01与02
A7: 证据充分可测品 | B7: 0 | C7: 当前所有正式成本缺失；真实成功盈利数也为0 | D7: 不采购、不投放、不上架
A8: 原始市场记录 | B8: 220 | C8: 原始采集并非本轮新增，币种与窗口异常 | D8: 见07与08
A9: 1688历史货源记录 | B9: 600 | C9: 起价及整条offer，不是当前同SKU报价 | D9: 见06；0价不能当免费
A10: 利润门槛 | B10: 20% 且 15元 | C10: 完全成本预计利润/商品收入；条件，不是保证 | D10: 基准、采购上限、压力三项一起审
A11: 单品测试总成本 | B11: ≤500 CNY | C11: 含采购、物流、平台费、推广、样品、售后等 | D11: 不能仅限制采购额
A12: 一分钟审一款的前提 | B12: 标准化证据已完整 | C12: 目标每日人工60分钟；首次建库与等待报价另计 | D12: 先做3天计时试跑
A13: 验收缺口 | B13: 未达到≥10个成功选品 | C13: 市场有效窗口、同SKU报价、运费费用及现金资料不全 | D13: 补齐数据后重跑；不以历史候选充数

Sheet 01_逐品结论
A1: 01 · 逐品结论
A2: 逐款列明冻结的证据与结论；方向性推断不是需求、质量、同款、利润或授权事实。真实经营成功只能由成熟实单对账证明。
A4: ID | B4: 产品方向 | C4: 本轮结论 | D4: 事实证据 | E4: 判断说明（推断） | F4: 拟验证差异 | G4: 缺口与风险 | H4: 补证顺序 | I4: 市场链接 | J4: 1688线索 | K4: 预计利润CNY | L4: 利润率 | M4: 测试成本CNY
A5: C01 | B5: 多尺寸拉链洗衣网袋套装 | C5: 待补证 | D5: 历史2026-09-10记录：价格原值75（币种未确认）；销量字段4957（窗口未核实）；1688历史起价0.6元；MOQ=1；代发原字段=True；未同SKU核验。 | E5: 洗衣防缠绕是明确可描述的使用场景，套装有机会分摊每单固定费；要用同规格成交与实物测试证实。 | F5: 细网、拉链保护套、明确尺寸与件数 | G5: PH/PHP与30天SKU销量；准确SKU规格及货源报价；包装计费重与运费；本店完整费项、活动、税与汇率；当前现金/未决损失；样品/合规/图权。比较网眼、拉链包边、尺寸和套装件数，不借竞品品牌。 | H5: A 优先补证：拉链开合与机洗测试；套装件数逐件对齐；取得主货源、完整成本后再判。 | I5: https://shopee.ph/product/1220516363/27528479375 | J5: https://detail.1688.com/offer/625255182969.html
A6: C02 | B6: 行李箱衣物分装收纳套装 | C6: 待补证 | D6: 历史2026-09-10记录：价格原值243（币种未确认）；销量字段68（窗口未核实）；1688历史起价7.8元；MOQ=1；代发原字段=False；未同SKU核验。 | E6: 衣物分装可与洗漱/鞋袋服务同类旅行客户；体积重和单件代发可能否定经济性。 | F6: 分区标签、尺寸图、套装清单 | G6: PH/PHP与30天SKU销量；准确SKU规格及货源报价；包装计费重与运费；本店完整费项、活动、税与汇率；当前现金/未决损失；样品/合规/图权。现有7.8元为历史起价且代发原字段为false，不能认定支持当前模式。 | H6: A 优先补证：体积重量；普通分装与压缩功能分开核实；取得主货源、完整成本后再判。 | I6: https://shopee.ph/product/550121387/14529056693 | J6: https://detail.1688.com/offer/847068328975.html
A7: C03 | B7: 挂钩式旅行洗漱收纳包 | C7: 待补证 | D7: 历史2026-09-10记录：价格原值110（币种未确认）；销量字段3470（窗口未核实）；未取得该方向可配对的1688货源证据。 | E7: 空洗漱包无需搭售化妆品，可突出悬挂和分仓；这是结构优势假设。 | F7: 可展开分区、挂钩、干湿收纳场景 | G7: PH/PHP与30天SKU销量；准确SKU规格及货源报价；包装计费重与运费；本店完整费项、活动、税与汇率；当前现金/未决损失；样品/合规/图权。主货源空缺，需核实挂钩强度、空包包装重；不含液体、不直接称防水。 | H7: A 优先补证：挂钩强度、拉链、湿擦测试；不带液体；取得主货源、完整成本后再判。 | I7: https://shopee.ph/product/1338796953/24944345450
A8: C04 | B8: 抽绳鞋子防尘收纳袋 | C8: 待补证 | D8: 历史2026-09-10记录：价格原值15（币种未确认）；销量字段102（窗口未核实）；未取得该方向可配对的1688货源证据。 | E8: 结构简单但低价方向容易被固定处理费和国际运费吃掉利润；可研究多件组合。 | F8: 多件组合、可辨识鞋型尺寸 | G8: PH/PHP与30天SKU销量；准确SKU规格及货源报价；包装计费重与运费；本店完整费项、活动、税与汇率；当前现金/未决损失；样品/合规/图权。多件组合会改变SKU和竞品可比性，不能拿单只销量配整套定价。 | H8: B 暂缓单卖：低客单单卖成本；抽绳牢度与布料厚度；取得主货源、完整成本后再判。 | I8: https://shopee.ph/product/699515539/25544554587
A9: C05 | B9: 衣柜悬挂手袋收纳袋 | C9: 待补证 | D9: 历史2026-09-10记录：价格原值168（币种未确认）；销量字段750（窗口未核实）；未取得该方向可配对的1688货源证据。 | E9: 能服务衣柜整理场景；悬挂袋的大包装体积可能使跨境物流不合算。 | F9: 袋位可见、适配衣柜尺寸 | G9: PH/PHP与30天SKU销量；准确SKU规格及货源报价；包装计费重与运费；本店完整费项、活动、税与汇率；当前现金/未决损失；样品/合规/图权。先取得折叠包装尺寸，再核承重和缝线；图片视觉轻薄不等于计费轻。 | H9: B 先看体积：承重、缝线、折叠包装体积；取得主货源、完整成本后再判。 | I9: https://shopee.ph/product/419236915/6185455937
A10: C06 | B10: 发夹与发圈挂式整理架 | C10: 待补证 | D10: 历史2026-09-10记录：价格原值40（币种未确认）；销量字段528（窗口未核实）；未取得该方向可配对的1688货源证据。 | E10: 有发饰整理用途，但低价竞争和挂装问题可能抬高售后成本。 | F10: 按发夹/发圈分区、展示实物尺寸 | G10: PH/PHP与30天SKU销量；准确SKU规格及货源报价；包装计费重与运费；本店完整费项、活动、税与汇率；当前现金/未决损失；样品/合规/图权。只研究成人收纳用途和无侵权图案；不能推断儿童用品准入。 | H10: B 低优先：挂钩数量、组装难度、素材版权；取得主货源、完整成本后再判。 | I10: https://shopee.ph/product/739548616/26901266092
A11: C07 | B11: 自粘桌面理线夹套装 | C11: 待补证 | D11: 历史2026-09-10记录：价格原值78（币种未确认）；销量字段923（窗口未核实）；1688历史起价0.4元；MOQ=2；代发原字段=True；未同SKU核验。 | E11: 桌面理线需求线索存在，但自粘属性、Choice样本及品牌字段冲突降低可比性。 | F11: 孔径清楚、安装说明、组合数量 | G11: PH/PHP与30天SKU销量；准确SKU规格及货源报价；包装计费重与运费；本店完整费项、活动、税与汇率；当前现金/未决损失；样品/合规/图权。背胶/成分和承运未知；先明确是否符合不做化学相关产品的边界。 | H11: C 属性待核：胶黏耐湿热、可适配线径；参考样本为Choice Global且品牌字段有冲突；取得主货源、完整成本后再判。 | I11: https://shopee.ph/product/196214868/24474649589 | J11: https://detail.1688.com/offer/723994327186.html
A12: C08 | B12: 厨房电器电源线绕线器 | C12: 待补证 | D12: 历史2026-09-10记录：价格原值39（币种未确认）；销量字段1223（窗口未核实）；未取得该方向可配对的1688货源证据。 | E12: 被动绕线工具可整理电器外部线材；背胶失效和靠近热源使用可能增加投诉。 | F12: 突出适配表面与安装位置 | G12: PH/PHP与30天SKU销量；准确SKU规格及货源报价；包装计费重与运费；本店完整费项、活动、税与汇率；当前现金/未决损失；样品/合规/图权。先证实无带电组件、胶黏属性、适配表面；不做电气安全承诺。 | H12: C 属性待核：脱胶与热源距离；不宣称防火或电气保护；取得主货源、完整成本后再判。 | I12: https://shopee.ph/product/1209340734/27308021764
A13: C09 | B13: 螺旋式线材整理保护管 | C13: 待补证 | D13: 历史2026-09-10记录：价格原值105（币种未确认）；销量字段522（窗口未核实）；未取得该方向可配对的1688货源证据。 | E13: 被动整理套管可按长度/直径区分用途；规格错配与安装难度可能拉低转化。 | F13: 按内径和长度售卖 | G13: PH/PHP与30天SKU销量；准确SKU规格及货源报价；包装计费重与运费；本店完整费项、活动、税与汇率；当前现金/未决损失；样品/合规/图权。核实每米/每卷单位，排除电气绝缘或阻燃认证诉求。 | H13: B 规格优先：规格与材质核实；不宣称防猫咬或绝缘认证；取得主货源、完整成本后再判。 | I13: https://shopee.ph/product/284375657/14488134409
A14: C10 | B14: 衣物粘毛滚筒加替换芯 | C14: 待补证 | D14: 历史2026-09-10记录：价格原值15（币种未确认）；销量字段2969（窗口未核实）；未取得该方向可配对的1688货源证据。 | E14: 替换芯可能形成后续需求，但本轮没有真实复购数据，不能计复购率。 | F14: 滚筒与替换芯组合、撕取演示 | G14: PH/PHP与30天SKU销量；准确SKU规格及货源报价；包装计费重与运费；本店完整费项、活动、税与汇率；当前现金/未决损失；样品/合规/图权。粘胶相关属性和剩余纸张数、撕取效果未核；先确认经营边界。 | H14: C 属性待核：纸张数、粘力、实际毛发清理测试；取得主货源、完整成本后再判。 | I14: https://shopee.ph/product/279498155/15750813899
A15: C11 | B15: 硅胶排水口毛发过滤片 | C15: 待补证 | D15: 历史2026-09-10记录：价格原值49（币种未确认）；销量字段647（窗口未核实）；未取得该方向可配对的1688货源证据。 | E15: 浴室排水口过滤是可验证的场景；低客单、孔径不匹配和排水慢可能否定方案。 | F15: 按孔径与排水口形状组合 | G15: PH/PHP与30天SKU销量；准确SKU规格及货源报价；包装计费重与运费；本店完整费项、活动、税与汇率；当前现金/未决损失；样品/合规/图权。只研究浴室非食品接触用途；不可声称抗菌或除臭。 | H15: B 低优先：排水速度、贴合度；不作杀菌除臭承诺；取得主货源、完整成本后再判。 | I15: https://shopee.ph/product/970194884/19694647631
A16: C12 | B16: 挂式塑料袋收纳袋 | C16: 待补证 | D16: 历史2026-09-10记录：价格原值27（币种未确认）；销量字段4053（窗口未核实）；未取得该方向可配对的1688货源证据。 | E16: 上装下抽可演示使用价值，但低价方向需验证组合后仍有市场需求。 | F16: 上装下抽、尺寸与悬挂方式清楚 | G16: PH/PHP与30天SKU销量；准确SKU规格及货源报价；包装计费重与运费；本店完整费项、活动、税与汇率；当前现金/未决损失；样品/合规/图权。需主货源、袋口和挂带样品检查；无证据不推导高转化。 | H16: B 暂缓单卖：低单价竞争；抽取顺畅、挂带强度；取得主货源、完整成本后再判。 | I16: https://shopee.ph/product/419236915/41276257375
A17: C13 | B17: 可重复使用粘扣理线带套装 | C17: 待补证 | D17: 历史2026-09-11记录：价格原值100（币种未确认）；销量字段149（窗口未核实）；1688历史起价0.03元；MOQ=1；代发原字段=True；未同SKU核验。 | E17: 不带胶的可重复绑带符合被动理线方向，套装有机会覆盖固定费。 | F17: 50条套装为竞品标题规格；自有销售套数和尺寸待确认 | G17: PH/PHP与30天SKU销量；准确SKU规格及货源报价；包装计费重与运费；本店完整费项、活动、税与汇率；当前现金/未决损失；样品/合规/图权。0.03元为历史起价，不是50条整套报价；自粘一词需确认是钩毛还是背胶。 | H17: A 优先补证：绑扎力度、反复开合、整套数量；不带胶、不宣称电气绝缘；取得主货源、完整成本后再判。 | I17: https://shopee.ph/product/264585346/20569033063 | J17: https://detail.1688.com/offer/594370725177.html
A18: C14 | B18: 网眼拉链旅行收纳包 | C18: 待补证 | D18: 历史2026-09-11记录：价格原值44（币种未确认）；销量字段677（窗口未核实）；1688历史起价1.13元；MOQ=1；代发原字段=False；未同SKU核验。 | E18: 网眼空包易做尺寸和可见性演示，可与旅行整理共享目标客群。 | F18: 网眼材质、拉链开合；长宽与单套数量待确认 | G18: PH/PHP与30天SKU销量；准确SKU规格及货源报价；包装计费重与运费；本店完整费项、活动、税与汇率；当前现金/未决损失；样品/合规/图权。1.13元历史起价且代发字段false；单件供货、尺寸、包重重新核实。 | H18: A 优先补证：拉链、接缝、网眼耐磨；只售空包；取得主货源、完整成本后再判。 | I18: https://shopee.ph/product/1229056552/25525886150 | J18: https://detail.1688.com/offer/965458977775.html
A19: C15 | B19: 五合一可折叠裤架 | C19: 待补证 | D19: 历史2026-09-11记录：价格原值69（币种未确认）；销量字段3423（窗口未核实）；1688历史起价8.5元；MOQ=1；代发原字段=True；未同SKU核验。 | E19: 折叠裤架有空间利用卖点，但金属杆、体积和关节质量可能不适合轻小跨境。 | F19: 五杆折叠结构；材质、尺寸与包装重待确认 | G19: PH/PHP与30天SKU销量；准确SKU规格及货源报价；包装计费重与运费；本店完整费项、活动、税与汇率；当前现金/未决损失；样品/合规/图权。历史8.5元不是当前SKU报价；包装超过500g即不符合当前门槛。 | H19: B 重量先筛：杆件毛刺、负重与折叠连接处；先排除超过500g；取得主货源、完整成本后再判。 | I19: https://shopee.ph/product/998991383/16595257849 | J19: https://detail.1688.com/offer/732898036456.html
A20: C16 | B20: 双层线材旅行收纳包 | C20: 待补证 | D20: 历史2026-09-11记录：价格原值105（币种未确认）；销量字段327（窗口未核实）；未取得该方向可配对的1688货源证据。 | E20: 双层空包可以表达线材分仓；不含任何带电配件时可研究相邻旅行需求。 | F20: 双层空收纳包；不含电线、电源或其他带电配件 | G20: PH/PHP与30天SKU销量；准确SKU规格及货源报价；包装计费重与运费；本店完整费项、活动、税与汇率；当前现金/未决损失；样品/合规/图权。主货源缺失；图中的充电器等不能默认属于套装，不复制防水宣称。 | H20: A 优先补证：分仓尺寸、拉链、空包净重；不可复制防水宣传；取得主货源、完整成本后再判。 | I20: https://shopee.ph/product/514999607/25305669141
A21: C17 | B21: 便携首饰分格收纳盒 | C21: 待补证 | D21: 历史2026-09-11记录：价格原值136（币种未确认）；销量字段415（窗口未核实）；未取得该方向可配对的1688货源证据。 | E21: 首饰分格有收纳用途，但硬盒体积和内衬质量可能增加成本与售后。 | F21: 耳环、戒指及项链分格；盒体材质与尺寸待确认 | G21: PH/PHP与30天SKU销量；准确SKU规格及货源报价；包装计费重与运费；本店完整费项、活动、税与汇率；当前现金/未决损失；样品/合规/图权。不含首饰，确认盒体尺寸、分隔固定、划伤测试及外观权利。 | H21: B 客单待核：隔断固定、合页/拉链、防刮；不含首饰；取得主货源、完整成本后再判。 | I21: https://shopee.ph/product/38727052/27810028091
A22: C18 | B22: 门背免打孔挂钩架 | C22: 待补证 | D22: 历史2026-09-11记录：价格原值169（币种未确认）；销量字段826（窗口未核实）；未取得该方向可配对的1688货源证据。 | E22: 挂门结构可避免胶粘，但门厚/门缝差异增加不适配风险。 | F22: 挂门式结构；门厚、挂钩数量及材质待确认 | G22: PH/PHP与30天SKU销量；准确SKU规格及货源报价；包装计费重与运费；本店完整费项、活动、税与汇率；当前现金/未决损失；样品/合规/图权。先测门厚范围、承重、防刮和包装重；不是宣称适配全部家庭。 | H22: B 适配先筛：门缝适配、防刮垫、承重、计费重量；不用胶；取得主货源、完整成本后再判。 | I22: https://shopee.ph/product/375375228/28740303369
A23: C19 | B23: 十夹式小件晾晒衣架 | C23: 待补证 | D23: 历史2026-09-11记录：价格原值82（币种未确认）；销量字段387（窗口未核实）；未取得该方向可配对的1688货源证据。 | E23: 小件晾晒用途明确；夹力、弹簧锈蚀和毛刺需要样品证据。 | F23: 标题为单个10夹；实物夹数、尺寸、材质待确认 | G23: PH/PHP与30天SKU销量；准确SKU规格及货源报价；包装计费重与运费；本店完整费项、活动、税与汇率；当前现金/未决损失；样品/合规/图权。每个10夹的准确件数、材质、包重与备用货源都缺。 | H23: B 质量先筛：夹力、夹齿毛刺、弹簧锈蚀和包装后重量；取得主货源、完整成本后再判。 | I23: https://shopee.ph/product/370984810/12536138081
A24: C20 | B24: 悬挂文件分袋整理袋 | C24: 待补证 | D24: 历史2026-09-11记录：价格原值99（币种未确认）；销量字段494（窗口未核实）；未取得该方向可配对的1688货源证据。 | E24: 空文件整理袋可拓展桌面收纳客群；跨不同用途的销量不能合并。 | F24: 布质多袋悬挂结构待实物确认；口袋尺寸适配A4需测量 | G24: PH/PHP与30天SKU销量；准确SKU规格及货源报价；包装计费重与运费；本店完整费项、活动、税与汇率；当前现金/未决损失；样品/合规/图权。A4适配须实际测量，文件袋不能用内衣收纳款销量替代。 | H24: B 规格先筛：仅空整理袋；不附书籍，不沿用内衣收纳不同规格销量；取得主货源、完整成本后再判。 | I24: https://shopee.ph/product/1344635572/43306697837
A25: C21 | B25: 桌面穿线孔盖 | C25: 待补证 | D25: 历史2026-09-11记录：价格原值72（币种未确认）；销量字段166（窗口未核实）；未取得该方向可配对的1688货源证据。 | E25: 孔盖属于被动整理配件，但购买依赖开孔尺寸，错配可能导致高退货。 | F25: 矩形ABS桌面孔盖；开孔尺寸与安装结构待确认 | G25: PH/PHP与30天SKU销量；准确SKU规格及货源报价；包装计费重与运费；本店完整费项、活动、税与汇率；当前现金/未决损失；样品/合规/图权。先验证常见尺寸的真实需求，排除受保护品牌/设计。 | H25: C 暂缓：尺寸匹配投诉风险；每种开孔规格单独验证；只售被动孔盖；取得主货源、完整成本后再判。 | I25: https://shopee.ph/product/1157080722/25286970958
A26: C22 | B26: 编织式线材整理套管 | C26: 待补证 | D26: 历史2026-09-11记录：价格原值313（币种未确认）；销量字段360（窗口未核实）；未取得该方向可配对的1688货源证据。 | E26: 编织套管可以研究被动收束用途，但长度和直径单位容易错配。 | F26: 竞品标题20米PET编织结构；直径、截段及单位待确认 | G26: PH/PHP与30天SKU销量；准确SKU规格及货源报价；包装计费重与运费；本店完整费项、活动、税与汇率；当前现金/未决损失；样品/合规/图权。20米竞品标题不能对应1米采购起价，绝缘/阻燃/防咬宣称须排除。 | H26: C 暂缓：承运/属性边界待核；仅考虑被动整理用途，绝缘阻燃等主张不采纳；取得主货源、完整成本后再判。 | I26: https://shopee.ph/product/969657190/22135470144

Sheet 02_逐项证据门槛
A1: 02 · 逐项证据门槛
A2: 达到数字门槛与证据有效是两件事。未核实、不适用和不通过分别记录；不生成虚假的总体通过率。
A4: ID | B4: 产品 | C4: 维度 | D4: 实际值/已知状态 | E4: 判定门槛 | F4: 符合程度 | G4: 解释及影响 | H4: 证据定位
A5: C01 | B5: 多尺寸拉链洗衣网袋套装 | C5: 数据质量 | D5: 原销量日=1970-01-01; PH查询/THB字典冲突 | E5: PH/PHP与明确30天SKU口径有效 | F5: 待补证 | G5: 不能用于定价、月销量、市场规模或利润事实 | H5: evidence/2026-09-10-candidates.json#/0
A6: C01 | B6: 多尺寸拉链洗衣网袋套装 | C6: 需求 | D6: 相关关键词原始样本20条；有效可比样本0；单条原始销量字段4957 | E6: ≥10可比商品/5店；30天合计≥300件；3店各≥30件 | F6: 待补证 | G6: 原始样本未证同规格和有效窗口，无法比较达标程度 | H6: evidence/2026-09-10-raw-observations.json#/market/1/result/content/0/text→JSON/data/2
A7: C01 | B7: 多尺寸拉链洗衣网袋套装 | C7: 竞争与价格 | D7: 价格原值75，币种未确认；本地/跨境可比组未完成 | E7: CR3≤70%；2跨境店各≥30件；到手价≤跨境中位数110% | F7: 待补证 | G7: 未计算价格分布或集中度，不能把单个畅销链接当入场证据 | H7: evidence/2026-09-10-candidates.json#/0
A8: C01 | B8: 多尺寸拉链洗衣网袋套装 | C8: 趋势与质量 | D8: 暂无可用3期趋势；样品未验 | E8: 同规格3期观察；样品确认差异点与重要质量项 | F8: 待补证 | G8: 拉链开合与机洗测试；套装件数逐件对齐 | H8: evidence/2026-09-10-candidates.json#/0
A9: C01 | B9: 多尺寸拉链洗衣网袋套装 | C9: 1688货源 | D9: 1688历史起价0.6元；MOQ=1；代发原字段=True；未同SKU核验 | E9: 24h内逐SKU报价；可单件代发；MOQ兼容；库存≥10套；备货≤48h | F9: 仅线索 | G9: 比较网眼、拉链包边、尺寸和套装件数，不借竞品品牌。 | H9: evidence/2026-09-10-raw-observations.json#/suppliers/0/result/content/0/text→JSON/data/5
A10: C01 | B10: 多尺寸拉链洗衣网袋套装 | C10: 物流履约 | D10: 包装尺寸/实重/体积重、净运费和各段时长未知 | E10: 计费重≤500g；物流≤收入25%；平台截止前24h缓冲 | F10: 待补证 | G10: 无运费无法算真实采购上限；目测尺寸不作证据 | H10: evidence/2026-09-10-candidates.json#/0
A11: C01 | B11: 多尺寸拉链洗衣网袋套装 | C11: 完全成本 | D11: 利润/利润率/最高采购价/压力利润均未知 | E11: ≥20%且≥15元；组合压力≥0；报价≤采购上限 | F11: 无法计算 | G11: 03和04保留空白，不用公共示例费率补齐实际成本 | H11: 03_逐品成本 / 04_费用明细
A12: C01 | B12: 多尺寸拉链洗衣网袋套装 | C12: 500元与资金 | D12: 测试单量、单品总成本、今日现金及未决损失未知 | E12: 单品累计总成本≤500；全店应急≥5000、月损失≤4000 | F12: 待补证 | G12: 启动20,000元不是今天余额；候选不能独立重复用同一现金 | H12: 05_500元与现金
A13: C01 | B13: 多尺寸拉链洗衣网袋套装 | C13: 合规与权利 | D13: 暂无逐SKU合规/图权/样品通过记录 | E13: 禁限售/认证/承运/品牌外观/图片授权均明确通过 | F13: 待补证 | G13: 普通空收纳用途仅为方向筛选，不等于合规结论；比较网眼、拉链包边、尺寸和套装件数，不借竞品品牌。 | H13: O03/O04；evidence/2026-09-10-candidates.json#/0
A14: C02 | B14: 行李箱衣物分装收纳套装 | C14: 数据质量 | D14: 原销量日=1970-01-01; PH查询/THB字典冲突 | E14: PH/PHP与明确30天SKU口径有效 | F14: 待补证 | G14: 不能用于定价、月销量、市场规模或利润事实 | H14: evidence/2026-09-10-candidates.json#/1
A15: C02 | B15: 行李箱衣物分装收纳套装 | C15: 需求 | D15: 相关关键词原始样本20条；有效可比样本0；单条原始销量字段68 | E15: ≥10可比商品/5店；30天合计≥300件；3店各≥30件 | F15: 待补证 | G15: 原始样本未证同规格和有效窗口，无法比较达标程度 | H15: evidence/2026-09-10-raw-observations.json#/market/3/result/content/0/text→JSON/data/6
... A202: C22 | B202: 编织式线材整理套管 | C202: 合规与权利 | D202: 暂无逐SKU合规/图权/样品通过记录 | E202: 禁限售/认证/承运/品牌外观/图片授权均明确通过 | F202: 待补证 | G202: 普通空收纳用途仅为方向筛选，不等于合规结论；20米竞品标题不能对应1米采购起价，绝缘/阻燃/防咬宣称须排除。 | H202: O03/O04；evidence/2026-09-11-candidates.json#/9

Sheet 03_逐品成本
A1: 03 · 逐品成本
A2: 一个销售单元=确定SKU一单（可以是套装）。成本预测不是已实现利润；仅填写准确报价和04全部费用，缺项不计算。报价观测≤24h另由Skill检查。修改后需重新生成审核结论。
A4: ID | B4: 产品 | C4: 券后商品PHP | D4: 额外补贴PHP | E4: CNY每PHP | F4: SKU采购价CNY | G4: 采购数量/套 | H4: 采购联动附加率 | I4: 样品拍摄等固定测试费 | J4: 测试计划单量 | K4: SKU报价证据 | L4: 报价截止 | M4: 费用口径审核 | N4: 费用完整 | O4: 其他成本CNY | P4: 压力其他成本 | Q4: 商品收入CNY | R4: 采购成本CNY | S4: 单件完全成本 | T4: 预计利润CNY | U4: 预计利润率 | V4: 采购上限CNY | W4: 组合压力利润 | X4: 测试总成本 | Y4: 500元最多测试单量 | Z4: 成本判定
A5: C01 | B5: 多尺寸拉链洗衣网袋套装 | M5: 待核实 | N5: =IF(COUNTIF('04_费用明细'!N5:N22,"完整")=18,"完整","待补证") -> 待补证 | O5: =IF(N5="完整",SUM('04_费用明细'!L5:L22),"") | P5: =IF(N5="完整",SUM('04_费用明细'!M5:M22),"") | Q5: =IF(AND(COUNT(C5:J5)=8,C5>0,D5>=0,E5>0,F5>=0,G5>0,G5=INT(G5),H5>=0,I5>=0,J5>0,J5=INT(J5),K5<>"",ISNUMBER(L5),L5>='00_审核入口'!$F$2,M5="已核实",N5="完整"),ROUND(ROUND((C5+D5)*E5,10),2),"") | R5: =IF(AND(COUNT(C5:J5)=8,C5>0,D5>=0,E5>0,F5>=0,G5>0,G5=INT(G5),H5>=0,I5>=0,J5>0,J5=INT(J5),K5<>"",ISNUMBER(L5),L5>='00_审核入口'!$F$2,M5="已核实",N5="完整"),ROUND(ROUND(F5*G5*(1+H5),10),2),"") | S5: =IF(AND(COUNT(C5:J5)=8,C5>0,D5>=0,E5>0,F5>=0,G5>0,G5=INT(G5),H5>=0,I5>=0,J5>0,J5=INT(J5),K5<>"",ISNUMBER(L5),L5>='00_审核入口'!$F$2,M5="已核实",N5="完整"),R5+O5,"") | T5: =IF(AND(COUNT(C5:J5)=8,C5>0,D5>=0,E5>0,F5>=0,G5>0,G5=INT(G5),H5>=0,I5>=0,J5>0,J5=INT(J5),K5<>"",ISNUMBER(L5),L5>='00_审核入口'!$F$2,M5="已核实",N5="完整"),Q5-S5,"") | U5: =IF(AND(COUNT(C5:J5)=8,C5>0,D5>=0,E5>0,F5>=0,G5>0,G5=INT(G5),H5>=0,I5>=0,J5>0,J5=INT(J5),K5<>"",ISNUMBER(L5),L5>='00_审核入口'!$F$2,M5="已核实",N5="完整"),IF(Q5>0,T5/Q5,""),"") | V5: =IF(AND(COUNT(C5:J5)=8,C5>0,D5>=0,E5>0,F5>=0,G5>0,G5=INT(G5),H5>=0,I5>=0,J5>0,J5=INT(J5),K5<>"",ISNUMBER(L5),L5>='00_审核入口'!$F$2,M5="已核实",N5="完整"),IF(Q5-O5-ROUNDUP(MAX(15,0.2*Q5),2)<0,"无非负可行采购价",ROUNDDOWN((Q5-O5-ROUNDUP(MAX(15,0.2*Q5),2)+0.005-0.0000000001)/(G5*(1+H5)),2)),"") | W5: =IF(AND(COUNT(C5:J5)=8,C5>0,D5>=0,E5>0,F5>=0,G5>0,G5=INT(G5),H5>=0,I5>=0,J5>0,J5=INT(J5),K5<>"",ISNUMBER(L5),L5>='00_审核入口'!$F$2,M5="已核实",N5="完整"),ROUND(ROUND((C5+D5)*E5*0.95,10),2)-ROUND(ROUND(F5*1.1*G5*(1+H5),10),2)-P5,"") | X5: =IF(AND(COUNT(C5:J5)=8,C5>0,D5>=0,E5>0,F5>=0,G5>0,G5=INT(G5),H5>=0,I5>=0,J5>0,J5=INT(J5),K5<>"",ISNUMBER(L5),L5>='00_审核入口'!$F$2,M5="已核实",N5="完整"),ROUND(I5+J5*S5,2),"") | Y5: =IF(AND(COUNT(C5:J5)=8,C5>0,D5>=0,E5>0,F5>=0,G5>0,G5=INT(G5),H5>=0,I5>=0,J5>0,J5=INT(J5),K5<>"",ISNUMBER(L5),L5>='00_审核入口'!$F$2,M5="已核实",N5="完整"),IF(S5>0,MAX(0,INT((500-I5)/S5)),""),"") | Z5: =IF(AND(COUNT(C5:J5)=8,C5>0,D5>=0,E5>0,F5>=0,G5>0,G5=INT(G5),H5>=0,I5>=0,J5>0,J5=INT(J5),K5<>"",ISNUMBER(L5),L5>='00_审核入口'!$F$2,M5="已核实",N5="完整"),IF(AND(T5>=15,U5>=0.2,W5>=0,X5<=500),"成本条件通过","成本条件不通过"),"待补证") -> 待补证
A6: C02 | B6: 行李箱衣物分装收纳套装 | M6: 待核实 | N6: =IF(COUNTIF('04_费用明细'!N23:N40,"完整")=18,"完整","待补证") -> 待补证 | O6: =IF(N6="完整",SUM('04_费用明细'!L23:L40),"") | P6: =IF(N6="完整",SUM('04_费用明细'!M23:M40),"") | Q6: =IF(AND(COUNT(C6:J6)=8,C6>0,D6>=0,E6>0,F6>=0,G6>0,G6=INT(G6),H6>=0,I6>=0,J6>0,J6=INT(J6),K6<>"",ISNUMBER(L6),L6>='00_审核入口'!$F$2,M6="已核实",N6="完整"),ROUND(ROUND((C6+D6)*E6,10),2),"") | R6: =IF(AND(COUNT(C6:J6)=8,C6>0,D6>=0,E6>0,F6>=0,G6>0,G6=INT(G6),H6>=0,I6>=0,J6>0,J6=INT(J6),K6<>"",ISNUMBER(L6),L6>='00_审核入口'!$F$2,M6="已核实",N6="完整"),ROUND(ROUND(F6*G6*(1+H6),10),2),"") | S6: =IF(AND(COUNT(C6:J6)=8,C6>0,D6>=0,E6>0,F6>=0,G6>0,G6=INT(G6),H6>=0,I6>=0,J6>0,J6=INT(J6),K6<>"",ISNUMBER(L6),L6>='00_审核入口'!$F$2,M6="已核实",N6="完整"),R6+O6,"") | T6: =IF(AND(COUNT(C6:J6)=8,C6>0,D6>=0,E6>0,F6>=0,G6>0,G6=INT(G6),H6>=0,I6>=0,J6>0,J6=INT(J6),K6<>"",ISNUMBER(L6),L6>='00_审核入口'!$F$2,M6="已核实",N6="完整"),Q6-S6,"") | U6: =IF(AND(COUNT(C6:J6)=8,C6>0,D6>=0,E6>0,F6>=0,G6>0,G6=INT(G6),H6>=0,I6>=0,J6>0,J6=INT(J6),K6<>"",ISNUMBER(L6),L6>='00_审核入口'!$F$2,M6="已核实",N6="完整"),IF(Q6>0,T6/Q6,""),"") | V6: =IF(AND(COUNT(C6:J6)=8,C6>0,D6>=0,E6>0,F6>=0,G6>0,G6=INT(G6),H6>=0,I6>=0,J6>0,J6=INT(J6),K6<>"",ISNUMBER(L6),L6>='00_审核入口'!$F$2,M6="已核实",N6="完整"),IF(Q6-O6-ROUNDUP(MAX(15,0.2*Q6),2)<0,"无非负可行采购价",ROUNDDOWN((Q6-O6-ROUNDUP(MAX(15,0.2*Q6),2)+0.005-0.0000000001)/(G6*(1+H6)),2)),"") | W6: =IF(AND(COUNT(C6:J6)=8,C6>0,D6>=0,E6>0,F6>=0,G6>0,G6=INT(G6),H6>=0,I6>=0,J6>0,J6=INT(J6),K6<>"",ISNUMBER(L6),L6>='00_审核入口'!$F$2,M6="已核实",N6="完整"),ROUND(ROUND((C6+D6)*E6*0.95,10),2)-ROUND(ROUND(F6*1.1*G6*(1+H6),10),2)-P6,"") | X6: =IF(AND(COUNT(C6:J6)=8,C6>0,D6>=0,E6>0,F6>=0,G6>0,G6=INT(G6),H6>=0,I6>=0,J6>0,J6=INT(J6),K6<>"",ISNUMBER(L6),L6>='00_审核入口'!$F$2,M6="已核实",N6="完整"),ROUND(I6+J6*S6,2),"") | Y6: =IF(AND(COUNT(C6:J6)=8,C6>0,D6>=0,E6>0,F6>=0,G6>0,G6=INT(G6),H6>=0,I6>=0,J6>0,J6=INT(J6),K6<>"",ISNUMBER(L6),L6>='00_审核入口'!$F$2,M6="已核实",N6="完整"),IF(S6>0,MAX(0,INT((500-I6)/S6)),""),"") | Z6: =IF(AND(COUNT(C6:J6)=8,C6>0,D6>=0,E6>0,F6>=0,G6>0,G6=INT(G6),H6>=0,I6>=0,J6>0,J6=INT(J6),K6<>"",ISNUMBER(L6),L6>='00_审核入口'!$F$2,M6="已核实",N6="完整"),IF(AND(T6>=15,U6>=0.2,W6>=0,X6<=500),"成本条件通过","成本条件不通过"),"待补证") -> 待补证
A7: C03 | B7: 挂钩式旅行洗漱收纳包 | M7: 待核实 | N7: =IF(COUNTIF('04_费用明细'!N41:N58,"完整")=18,"完整","待补证") -> 待补证 | O7: =IF(N7="完整",SUM('04_费用明细'!L41:L58),"") | P7: =IF(N7="完整",SUM('04_费用明细'!M41:M58),"") | Q7: =IF(AND(COUNT(C7:J7)=8,C7>0,D7>=0,E7>0,F7>=0,G7>0,G7=INT(G7),H7>=0,I7>=0,J7>0,J7=INT(J7),K7<>"",ISNUMBER(L7),L7>='00_审核入口'!$F$2,M7="已核实",N7="完整"),ROUND(ROUND((C7+D7)*E7,10),2),"") | R7: =IF(AND(COUNT(C7:J7)=8,C7>0,D7>=0,E7>0,F7>=0,G7>0,G7=INT(G7),H7>=0,I7>=0,J7>0,J7=INT(J7),K7<>"",ISNUMBER(L7),L7>='00_审核入口'!$F$2,M7="已核实",N7="完整"),ROUND(ROUND(F7*G7*(1+H7),10),2),"") | S7: =IF(AND(COUNT(C7:J7)=8,C7>0,D7>=0,E7>0,F7>=0,G7>0,G7=INT(G7),H7>=0,I7>=0,J7>0,J7=INT(J7),K7<>"",ISNUMBER(L7),L7>='00_审核入口'!$F$2,M7="已核实",N7="完整"),R7+O7,"") | T7: =IF(AND(COUNT(C7:J7)=8,C7>0,D7>=0,E7>0,F7>=0,G7>0,G7=INT(G7),H7>=0,I7>=0,J7>0,J7=INT(J7),K7<>"",ISNUMBER(L7),L7>='00_审核入口'!$F$2,M7="已核实",N7="完整"),Q7-S7,"") | U7: =IF(AND(COUNT(C7:J7)=8,C7>0,D7>=0,E7>0,F7>=0,G7>0,G7=INT(G7),H7>=0,I7>=0,J7>0,J7=INT(J7),K7<>"",ISNUMBER(L7),L7>='00_审核入口'!$F$2,M7="已核实",N7="完整"),IF(Q7>0,T7/Q7,""),"") | V7: =IF(AND(COUNT(C7:J7)=8,C7>0,D7>=0,E7>0,F7>=0,G7>0,G7=INT(G7),H7>=0,I7>=0,J7>0,J7=INT(J7),K7<>"",ISNUMBER(L7),L7>='00_审核入口'!$F$2,M7="已核实",N7="完整"),IF(Q7-O7-ROUNDUP(MAX(15,0.2*Q7),2)<0,"无非负可行采购价",ROUNDDOWN((Q7-O7-ROUNDUP(MAX(15,0.2*Q7),2)+0.005-0.0000000001)/(G7*(1+H7)),2)),"") | W7: =IF(AND(COUNT(C7:J7)=8,C7>0,D7>=0,E7>0,F7>=0,G7>0,G7=INT(G7),H7>=0,I7>=0,J7>0,J7=INT(J7),K7<>"",ISNUMBER(L7),L7>='00_审核入口'!$F$2,M7="已核实",N7="完整"),ROUND(ROUND((C7+D7)*E7*0.95,10),2)-ROUND(ROUND(F7*1.1*G7*(1+H7),10),2)-P7,"") | X7: =IF(AND(COUNT(C7:J7)=8,C7>0,D7>=0,E7>0,F7>=0,G7>0,G7=INT(G7),H7>=0,I7>=0,J7>0,J7=INT(J7),K7<>"",ISNUMBER(L7),L7>='00_审核入口'!$F$2,M7="已核实",N7="完整"),ROUND(I7+J7*S7,2),"") | Y7: =IF(AND(COUNT(C7:J7)=8,C7>0,D7>=0,E7>0,F7>=0,G7>0,G7=INT(G7),H7>=0,I7>=0,J7>0,J7=INT(J7),K7<>"",ISNUMBER(L7),L7>='00_审核入口'!$F$2,M7="已核实",N7="完整"),IF(S7>0,MAX(0,INT((500-I7)/S7)),""),"") | Z7: =IF(AND(COUNT(C7:J7)=8,C7>0,D7>=0,E7>0,F7>=0,G7>0,G7=INT(G7),H7>=0,I7>=0,J7>0,J7=INT(J7),K7<>"",ISNUMBER(L7),L7>='00_审核入口'!$F$2,M7="已核实",N7="完整"),IF(AND(T7>=15,U7>=0.2,W7>=0,X7<=500),"成本条件通过","成本条件不通过"),"待补证") -> 待补证
A8: C04 | B8: 抽绳鞋子防尘收纳袋 | M8: 待核实 | N8: =IF(COUNTIF('04_费用明细'!N59:N76,"完整")=18,"完整","待补证") -> 待补证 | O8: =IF(N8="完整",SUM('04_费用明细'!L59:L76),"") | P8: =IF(N8="完整",SUM('04_费用明细'!M59:M76),"") | Q8: =IF(AND(COUNT(C8:J8)=8,C8>0,D8>=0,E8>0,F8>=0,G8>0,G8=INT(G8),H8>=0,I8>=0,J8>0,J8=INT(J8),K8<>"",ISNUMBER(L8),L8>='00_审核入口'!$F$2,M8="已核实",N8="完整"),ROUND(ROUND((C8+D8)*E8,10),2),"") | R8: =IF(AND(COUNT(C8:J8)=8,C8>0,D8>=0,E8>0,F8>=0,G8>0,G8=INT(G8),H8>=0,I8>=0,J8>0,J8=INT(J8),K8<>"",ISNUMBER(L8),L8>='00_审核入口'!$F$2,M8="已核实",N8="完整"),ROUND(ROUND(F8*G8*(1+H8),10),2),"") | S8: =IF(AND(COUNT(C8:J8)=8,C8>0,D8>=0,E8>0,F8>=0,G8>0,G8=INT(G8),H8>=0,I8>=0,J8>0,J8=INT(J8),K8<>"",ISNUMBER(L8),L8>='00_审核入口'!$F$2,M8="已核实",N8="完整"),R8+O8,"") | T8: =IF(AND(COUNT(C8:J8)=8,C8>0,D8>=0,E8>0,F8>=0,G8>0,G8=INT(G8),H8>=0,I8>=0,J8>0,J8=INT(J8),K8<>"",ISNUMBER(L8),L8>='00_审核入口'!$F$2,M8="已核实",N8="完整"),Q8-S8,"") | U8: =IF(AND(COUNT(C8:J8)=8,C8>0,D8>=0,E8>0,F8>=0,G8>0,G8=INT(G8),H8>=0,I8>=0,J8>0,J8=INT(J8),K8<>"",ISNUMBER(L8),L8>='00_审核入口'!$F$2,M8="已核实",N8="完整"),IF(Q8>0,T8/Q8,""),"") | V8: =IF(AND(COUNT(C8:J8)=8,C8>0,D8>=0,E8>0,F8>=0,G8>0,G8=INT(G8),H8>=0,I8>=0,J8>0,J8=INT(J8),K8<>"",ISNUMBER(L8),L8>='00_审核入口'!$F$2,M8="已核实",N8="完整"),IF(Q8-O8-ROUNDUP(MAX(15,0.2*Q8),2)<0,"无非负可行采购价",ROUNDDOWN((Q8-O8-ROUNDUP(MAX(15,0.2*Q8),2)+0.005-0.0000000001)/(G8*(1+H8)),2)),"") | W8: =IF(AND(COUNT(C8:J8)=8,C8>0,D8>=0,E8>0,F8>=0,G8>0,G8=INT(G8),H8>=0,I8>=0,J8>0,J8=INT(J8),K8<>"",ISNUMBER(L8),L8>='00_审核入口'!$F$2,M8="已核实",N8="完整"),ROUND(ROUND((C8+D8)*E8*0.95,10),2)-ROUND(ROUND(F8*1.1*G8*(1+H8),10),2)-P8,"") | X8: =IF(AND(COUNT(C8:J8)=8,C8>0,D8>=0,E8>0,F8>=0,G8>0,G8=INT(G8),H8>=0,I8>=0,J8>0,J8=INT(J8),K8<>"",ISNUMBER(L8),L8>='00_审核入口'!$F$2,M8="已核实",N8="完整"),ROUND(I8+J8*S8,2),"") | Y8: =IF(AND(COUNT(C8:J8)=8,C8>0,D8>=0,E8>0,F8>=0,G8>0,G8=INT(G8),H8>=0,I8>=0,J8>0,J8=INT(J8),K8<>"",ISNUMBER(L8),L8>='00_审核入口'!$F$2,M8="已核实",N8="完整"),IF(S8>0,MAX(0,INT((500-I8)/S8)),""),"") | Z8: =IF(AND(COUNT(C8:J8)=8,C8>0,D8>=0,E8>0,F8>=0,G8>0,G8=INT(G8),H8>=0,I8>=0,J8>0,J8=INT(J8),K8<>"",ISNUMBER(L8),L8>='00_审核入口'!$F$2,M8="已核实",N8="完整"),IF(AND(T8>=15,U8>=0.2,W8>=0,X8<=500),"成本条件通过","成本条件不通过"),"待补证") -> 待补证
A9: C05 | B9: 衣柜悬挂手袋收纳袋 | M9: 待核实 | N9: =IF(COUNTIF('04_费用明细'!N77:N94,"完整")=18,"完整","待补证") -> 待补证 | O9: =IF(N9="完整",SUM('04_费用明细'!L77:L94),"") | P9: =IF(N9="完整",SUM('04_费用明细'!M77:M94),"") | Q9: =IF(AND(COUNT(C9:J9)=8,C9>0,D9>=0,E9>0,F9>=0,G9>0,G9=INT(G9),H9>=0,I9>=0,J9>0,J9=INT(J9),K9<>"",ISNUMBER(L9),L9>='00_审核入口'!$F$2,M9="已核实",N9="完整"),ROUND(ROUND((C9+D9)*E9,10),2),"") | R9: =IF(AND(COUNT(C9:J9)=8,C9>0,D9>=0,E9>0,F9>=0,G9>0,G9=INT(G9),H9>=0,I9>=0,J9>0,J9=INT(J9),K9<>"",ISNUMBER(L9),L9>='00_审核入口'!$F$2,M9="已核实",N9="完整"),ROUND(ROUND(F9*G9*(1+H9),10),2),"") | S9: =IF(AND(COUNT(C9:J9)=8,C9>0,D9>=0,E9>0,F9>=0,G9>0,G9=INT(G9),H9>=0,I9>=0,J9>0,J9=INT(J9),K9<>"",ISNUMBER(L9),L9>='00_审核入口'!$F$2,M9="已核实",N9="完整"),R9+O9,"") | T9: =IF(AND(COUNT(C9:J9)=8,C9>0,D9>=0,E9>0,F9>=0,G9>0,G9=INT(G9),H9>=0,I9>=0,J9>0,J9=INT(J9),K9<>"",ISNUMBER(L9),L9>='00_审核入口'!$F$2,M9="已核实",N9="完整"),Q9-S9,"") | U9: =IF(AND(COUNT(C9:J9)=8,C9>0,D9>=0,E9>0,F9>=0,G9>0,G9=INT(G9),H9>=0,I9>=0,J9>0,J9=INT(J9),K9<>"",ISNUMBER(L9),L9>='00_审核入口'!$F$2,M9="已核实",N9="完整"),IF(Q9>0,T9/Q9,""),"") | V9: =IF(AND(COUNT(C9:J9)=8,C9>0,D9>=0,E9>0,F9>=0,G9>0,G9=INT(G9),H9>=0,I9>=0,J9>0,J9=INT(J9),K9<>"",ISNUMBER(L9),L9>='00_审核入口'!$F$2,M9="已核实",N9="完整"),IF(Q9-O9-ROUNDUP(MAX(15,0.2*Q9),2)<0,"无非负可行采购价",ROUNDDOWN((Q9-O9-ROUNDUP(MAX(15,0.2*Q9),2)+0.005-0.0000000001)/(G9*(1+H9)),2)),"") | W9: =IF(AND(COUNT(C9:J9)=8,C9>0,D9>=0,E9>0,F9>=0,G9>0,G9=INT(G9),H9>=0,I9>=0,J9>0,J9=INT(J9),K9<>"",ISNUMBER(L9),L9>='00_审核入口'!$F$2,M9="已核实",N9="完整"),ROUND(ROUND((C9+D9)*E9*0.95,10),2)-ROUND(ROUND(F9*1.1*G9*(1+H9),10),2)-P9,"") | X9: =IF(AND(COUNT(C9:J9)=8,C9>0,D9>=0,E9>0,F9>=0,G9>0,G9=INT(G9),H9>=0,I9>=0,J9>0,J9=INT(J9),K9<>"",ISNUMBER(L9),L9>='00_审核入口'!$F$2,M9="已核实",N9="完整"),ROUND(I9+J9*S9,2),"") | Y9: =IF(AND(COUNT(C9:J9)=8,C9>0,D9>=0,E9>0,F9>=0,G9>0,G9=INT(G9),H9>=0,I9>=0,J9>0,J9=INT(J9),K9<>"",ISNUMBER(L9),L9>='00_审核入口'!$F$2,M9="已核实",N9="完整"),IF(S9>0,MAX(0,INT((500-I9)/S9)),""),"") | Z9: =IF(AND(COUNT(C9:J9)=8,C9>0,D9>=0,E9>0,F9>=0,G9>0,G9=INT(G9),H9>=0,I9>=0,J9>0,J9=INT(J9),K9<>"",ISNUMBER(L9),L9>='00_审核入口'!$F$2,M9="已核实",N9="完整"),IF(AND(T9>=15,U9>=0.2,W9>=0,X9<=500),"成本条件通过","成本条件不通过"),"待补证") -> 待补证
A10: C06 | B10: 发夹与发圈挂式整理架 | M10: 待核实 | N10: =IF(COUNTIF('04_费用明细'!N95:N112,"完整")=18,"完整","待补证") -> 待补证 | O10: =IF(N10="完整",SUM('04_费用明细'!L95:L112),"") | P10: =IF(N10="完整",SUM('04_费用明细'!M95:M112),"") | Q10: =IF(AND(COUNT(C10:J10)=8,C10>0,D10>=0,E10>0,F10>=0,G10>0,G10=INT(G10),H10>=0,I10>=0,J10>0,J10=INT(J10),K10<>"",ISNUMBER(L10),L10>='00_审核入口'!$F$2,M10="已核实",N10="完整"),ROUND(ROUND((C10+D10)*E10,10),2),"") | R10: =IF(AND(COUNT(C10:J10)=8,C10>0,D10>=0,E10>0,F10>=0,G10>0,G10=INT(G10),H10>=0,I10>=0,J10>0,J10=INT(J10),K10<>"",ISNUMBER(L10),L10>='00_审核入口'!$F$2,M10="已核实",N10="完整"),ROUND(ROUND(F10*G10*(1+H10),10),2),"") | S10: =IF(AND(COUNT(C10:J10)=8,C10>0,D10>=0,E10>0,F10>=0,G10>0,G10=INT(G10),H10>=0,I10>=0,J10>0,J10=INT(J10),K10<>"",ISNUMBER(L10),L10>='00_审核入口'!$F$2,M10="已核实",N10="完整"),R10+O10,"") | T10: =IF(AND(COUNT(C10:J10)=8,C10>0,D10>=0,E10>0,F10>=0,G10>0,G10=INT(G10),H10>=0,I10>=0,J10>0,J10=INT(J10),K10<>"",ISNUMBER(L10),L10>='00_审核入口'!$F$2,M10="已核实",N10="完整"),Q10-S10,"") | U10: =IF(AND(COUNT(C10:J10)=8,C10>0,D10>=0,E10>0,F10>=0,G10>0,G10=INT(G10),H10>=0,I10>=0,J10>0,J10=INT(J10),K10<>"",ISNUMBER(L10),L10>='00_审核入口'!$F$2,M10="已核实",N10="完整"),IF(Q10>0,T10/Q10,""),"") | V10: =IF(AND(COUNT(C10:J10)=8,C10>0,D10>=0,E10>0,F10>=0,G10>0,G10=INT(G10),H10>=0,I10>=0,J10>0,J10=INT(J10),K10<>"",ISNUMBER(L10),L10>='00_审核入口'!$F$2,M10="已核实",N10="完整"),IF(Q10-O10-ROUNDUP(MAX(15,0.2*Q10),2)<0,"无非负可行采购价",ROUNDDOWN((Q10-O10-ROUNDUP(MAX(15,0.2*Q10),2)+0.005-0.0000000001)/(G10*(1+H10)),2)),"") | W10: =IF(AND(COUNT(C10:J10)=8,C10>0,D10>=0,E10>0,F10>=0,G10>0,G10=INT(G10),H10>=0,I10>=0,J10>0,J10=INT(J10),K10<>"",ISNUMBER(L10),L10>='00_审核入口'!$F$2,M10="已核实",N10="完整"),ROUND(ROUND((C10+D10)*E10*0.95,10),2)-ROUND(ROUND(F10*1.1*G10*(1+H10),10),2)-P10,"") | X10: =IF(AND(COUNT(C10:J10)=8,C10>0,D10>=0,E10>0,F10>=0,G10>0,G10=INT(G10),H10>=0,I10>=0,J10>0,J10=INT(J10),K10<>"",ISNUMBER(L10),L10>='00_审核入口'!$F$2,M10="已核实",N10="完整"),ROUND(I10+J10*S10,2),"") | Y10: =IF(AND(COUNT(C10:J10)=8,C10>0,D10>=0,E10>0,F10>=0,G10>0,G10=INT(G10),H10>=0,I10>=0,J10>0,J10=INT(J10),K10<>"",ISNUMBER(L10),L10>='00_审核入口'!$F$2,M10="已核实",N10="完整"),IF(S10>0,MAX(0,INT((500-I10)/S10)),""),"") | Z10: =IF(AND(COUNT(C10:J10)=8,C10>0,D10>=0,E10>0,F10>=0,G10>0,G10=INT(G10),H10>=0,I10>=0,J10>0,J10=INT(J10),K10<>"",ISNUMBER(L10),L10>='00_审核入口'!$F$2,M10="已核实",N10="完整"),IF(AND(T10>=15,U10>=0.2,W10>=0,X10<=500),"成本条件通过","成本条件不通过"),"待补证") -> 待补证
A11: C07 | B11: 自粘桌面理线夹套装 | M11: 待核实 | N11: =IF(COUNTIF('04_费用明细'!N113:N130,"完整")=18,"完整","待补证") -> 待补证 | O11: =IF(N11="完整",SUM('04_费用明细'!L113:L130),"") | P11: =IF(N11="完整",SUM('04_费用明细'!M113:M130),"") | Q11: =IF(AND(COUNT(C11:J11)=8,C11>0,D11>=0,E11>0,F11>=0,G11>0,G11=INT(G11),H11>=0,I11>=0,J11>0,J11=INT(J11),K11<>"",ISNUMBER(L11),L11>='00_审核入口'!$F$2,M11="已核实",N11="完整"),ROUND(ROUND((C11+D11)*E11,10),2),"") | R11: =IF(AND(COUNT(C11:J11)=8,C11>0,D11>=0,E11>0,F11>=0,G11>0,G11=INT(G11),H11>=0,I11>=0,J11>0,J11=INT(J11),K11<>"",ISNUMBER(L11),L11>='00_审核入口'!$F$2,M11="已核实",N11="完整"),ROUND(ROUND(F11*G11*(1+H11),10),2),"") | S11: =IF(AND(COUNT(C11:J11)=8,C11>0,D11>=0,E11>0,F11>=0,G11>0,G11=INT(G11),H11>=0,I11>=0,J11>0,J11=INT(J11),K11<>"",ISNUMBER(L11),L11>='00_审核入口'!$F$2,M11="已核实",N11="完整"),R11+O11,"") | T11: =IF(AND(COUNT(C11:J11)=8,C11>0,D11>=0,E11>0,F11>=0,G11>0,G11=INT(G11),H11>=0,I11>=0,J11>0,J11=INT(J11),K11<>"",ISNUMBER(L11),L11>='00_审核入口'!$F$2,M11="已核实",N11="完整"),Q11-S11,"") | U11: =IF(AND(COUNT(C11:J11)=8,C11>0,D11>=0,E11>0,F11>=0,G11>0,G11=INT(G11),H11>=0,I11>=0,J11>0,J11=INT(J11),K11<>"",ISNUMBER(L11),L11>='00_审核入口'!$F$2,M11="已核实",N11="完整"),IF(Q11>0,T11/Q11,""),"") | V11: =IF(AND(COUNT(C11:J11)=8,C11>0,D11>=0,E11>0,F11>=0,G11>0,G11=INT(G11),H11>=0,I11>=0,J11>0,J11=INT(J11),K11<>"",ISNUMBER(L11),L11>='00_审核入口'!$F$2,M11="已核实",N11="完整"),IF(Q11-O11-ROUNDUP(MAX(15,0.2*Q11),2)<0,"无非负可行采购价",ROUNDDOWN((Q11-O11-ROUNDUP(MAX(15,0.2*Q11),2)+0.005-0.0000000001)/(G11*(1+H11)),2)),"") | W11: =IF(AND(COUNT(C11:J11)=8,C11>0,D11>=0,E11>0,F11>=0,G11>0,G11=INT(G11),H11>=0,I11>=0,J11>0,J11=INT(J11),K11<>"",ISNUMBER(L11),L11>='00_审核入口'!$F$2,M11="已核实",N11="完整"),ROUND(ROUND((C11+D11)*E11*0.95,10),2)-ROUND(ROUND(F11*1.1*G11*(1+H11),10),2)-P11,"") | X11: =IF(AND(COUNT(C11:J11)=8,C11>0,D11>=0,E11>0,F11>=0,G11>0,G11=INT(G11),H11>=0,I11>=0,J11>0,J11=INT(J11),K11<>"",ISNUMBER(L11),L11>='00_审核入口'!$F$2,M11="已核实",N11="完整"),ROUND(I11+J11*S11,2),"") | Y11: =IF(AND(COUNT(C11:J11)=8,C11>0,D11>=0,E11>0,F11>=0,G11>0,G11=INT(G11),H11>=0,I11>=0,J11>0,J11=INT(J11),K11<>"",ISNUMBER(L11),L11>='00_审核入口'!$F$2,M11="已核实",N11="完整"),IF(S11>0,MAX(0,INT((500-I11)/S11)),""),"") | Z11: =IF(AND(COUNT(C11:J11)=8,C11>0,D11>=0,E11>0,F11>=0,G11>0,G11=INT(G11),H11>=0,I11>=0,J11>0,J11=INT(J11),K11<>"",ISNUMBER(L11),L11>='00_审核入口'!$F$2,M11="已核实",N11="完整"),IF(AND(T11>=15,U11>=0.2,W11>=0,X11<=500),"成本条件通过","成本条件不通过"),"待补证") -> 待补证
A12: C08 | B12: 厨房电器电源线绕线器 | M12: 待核实 | N12: =IF(COUNTIF('04_费用明细'!N131:N148,"完整")=18,"完整","待补证") -> 待补证 | O12: =IF(N12="完整",SUM('04_费用明细'!L131:L148),"") | P12: =IF(N12="完整",SUM('04_费用明细'!M131:M148),"") | Q12: =IF(AND(COUNT(C12:J12)=8,C12>0,D12>=0,E12>0,F12>=0,G12>0,G12=INT(G12),H12>=0,I12>=0,J12>0,J12=INT(J12),K12<>"",ISNUMBER(L12),L12>='00_审核入口'!$F$2,M12="已核实",N12="完整"),ROUND(ROUND((C12+D12)*E12,10),2),"") | R12: =IF(AND(COUNT(C12:J12)=8,C12>0,D12>=0,E12>0,F12>=0,G12>0,G12=INT(G12),H12>=0,I12>=0,J12>0,J12=INT(J12),K12<>"",ISNUMBER(L12),L12>='00_审核入口'!$F$2,M12="已核实",N12="完整"),ROUND(ROUND(F12*G12*(1+H12),10),2),"") | S12: =IF(AND(COUNT(C12:J12)=8,C12>0,D12>=0,E12>0,F12>=0,G12>0,G12=INT(G12),H12>=0,I12>=0,J12>0,J12=INT(J12),K12<>"",ISNUMBER(L12),L12>='00_审核入口'!$F$2,M12="已核实",N12="完整"),R12+O12,"") | T12: =IF(AND(COUNT(C12:J12)=8,C12>0,D12>=0,E12>0,F12>=0,G12>0,G12=INT(G12),H12>=0,I12>=0,J12>0,J12=INT(J12),K12<>"",ISNUMBER(L12),L12>='00_审核入口'!$F$2,M12="已核实",N12="完整"),Q12-S12,"") | U12: =IF(AND(COUNT(C12:J12)=8,C12>0,D12>=0,E12>0,F12>=0,G12>0,G12=INT(G12),H12>=0,I12>=0,J12>0,J12=INT(J12),K12<>"",ISNUMBER(L12),L12>='00_审核入口'!$F$2,M12="已核实",N12="完整"),IF(Q12>0,T12/Q12,""),"") | V12: =IF(AND(COUNT(C12:J12)=8,C12>0,D12>=0,E12>0,F12>=0,G12>0,G12=INT(G12),H12>=0,I12>=0,J12>0,J12=INT(J12),K12<>"",ISNUMBER(L12),L12>='00_审核入口'!$F$2,M12="已核实",N12="完整"),IF(Q12-O12-ROUNDUP(MAX(15,0.2*Q12),2)<0,"无非负可行采购价",ROUNDDOWN((Q12-O12-ROUNDUP(MAX(15,0.2*Q12),2)+0.005-0.0000000001)/(G12*(1+H12)),2)),"") | W12: =IF(AND(COUNT(C12:J12)=8,C12>0,D12>=0,E12>0,F12>=0,G12>0,G12=INT(G12),H12>=0,I12>=0,J12>0,J12=INT(J12),K12<>"",ISNUMBER(L12),L12>='00_审核入口'!$F$2,M12="已核实",N12="完整"),ROUND(ROUND((C12+D12)*E12*0.95,10),2)-ROUND(ROUND(F12*1.1*G12*(1+H12),10),2)-P12,"") | X12: =IF(AND(COUNT(C12:J12)=8,C12>0,D12>=0,E12>0,F12>=0,G12>0,G12=INT(G12),H12>=0,I12>=0,J12>0,J12=INT(J12),K12<>"",ISNUMBER(L12),L12>='00_审核入口'!$F$2,M12="已核实",N12="完整"),ROUND(I12+J12*S12,2),"") | Y12: =IF(AND(COUNT(C12:J12)=8,C12>0,D12>=0,E12>0,F12>=0,G12>0,G12=INT(G12),H12>=0,I12>=0,J12>0,J12=INT(J12),K12<>"",ISNUMBER(L12),L12>='00_审核入口'!$F$2,M12="已核实",N12="完整"),IF(S12>0,MAX(0,INT((500-I12)/S12)),""),"") | Z12: =IF(AND(COUNT(C12:J12)=8,C12>0,D12>=0,E12>0,F12>=0,G12>0,G12=INT(G12),H12>=0,I12>=0,J12>0,J12=INT(J12),K12<>"",ISNUMBER(L12),L12>='00_审核入口'!$F$2,M12="已核实",N12="完整"),IF(AND(T12>=15,U12>=0.2,W12>=0,X12<=500),"成本条件通过","成本条件不通过"),"待补证") -> 待补证
A13: C09 | B13: 螺旋式线材整理保护管 | M13: 待核实 | N13: =IF(COUNTIF('04_费用明细'!N149:N166,"完整")=18,"完整","待补证") -> 待补证 | O13: =IF(N13="完整",SUM('04_费用明细'!L149:L166),"") | P13: =IF(N13="完整",SUM('04_费用明细'!M149:M166),"") | Q13: =IF(AND(COUNT(C13:J13)=8,C13>0,D13>=0,E13>0,F13>=0,G13>0,G13=INT(G13),H13>=0,I13>=0,J13>0,J13=INT(J13),K13<>"",ISNUMBER(L13),L13>='00_审核入口'!$F$2,M13="已核实",N13="完整"),ROUND(ROUND((C13+D13)*E13,10),2),"") | R13: =IF(AND(COUNT(C13:J13)=8,C13>0,D13>=0,E13>0,F13>=0,G13>0,G13=INT(G13),H13>=0,I13>=0,J13>0,J13=INT(J13),K13<>"",ISNUMBER(L13),L13>='00_审核入口'!$F$2,M13="已核实",N13="完整"),ROUND(ROUND(F13*G13*(1+H13),10),2),"") | S13: =IF(AND(COUNT(C13:J13)=8,C13>0,D13>=0,E13>0,F13>=0,G13>0,G13=INT(G13),H13>=0,I13>=0,J13>0,J13=INT(J13),K13<>"",ISNUMBER(L13),L13>='00_审核入口'!$F$2,M13="已核实",N13="完整"),R13+O13,"") | T13: =IF(AND(COUNT(C13:J13)=8,C13>0,D13>=0,E13>0,F13>=0,G13>0,G13=INT(G13),H13>=0,I13>=0,J13>0,J13=INT(J13),K13<>"",ISNUMBER(L13),L13>='00_审核入口'!$F$2,M13="已核实",N13="完整"),Q13-S13,"") | U13: =IF(AND(COUNT(C13:J13)=8,C13>0,D13>=0,E13>0,F13>=0,G13>0,G13=INT(G13),H13>=0,I13>=0,J13>0,J13=INT(J13),K13<>"",ISNUMBER(L13),L13>='00_审核入口'!$F$2,M13="已核实",N13="完整"),IF(Q13>0,T13/Q13,""),"") | V13: =IF(AND(COUNT(C13:J13)=8,C13>0,D13>=0,E13>0,F13>=0,G13>0,G13=INT(G13),H13>=0,I13>=0,J13>0,J13=INT(J13),K13<>"",ISNUMBER(L13),L13>='00_审核入口'!$F$2,M13="已核实",N13="完整"),IF(Q13-O13-ROUNDUP(MAX(15,0.2*Q13),2)<0,"无非负可行采购价",ROUNDDOWN((Q13-O13-ROUNDUP(MAX(15,0.2*Q13),2)+0.005-0.0000000001)/(G13*(1+H13)),2)),"") | W13: =IF(AND(COUNT(C13:J13)=8,C13>0,D13>=0,E13>0,F13>=0,G13>0,G13=INT(G13),H13>=0,I13>=0,J13>0,J13=INT(J13),K13<>"",ISNUMBER(L13),L13>='00_审核入口'!$F$2,M13="已核实",N13="完整"),ROUND(ROUND((C13+D13)*E13*0.95,10),2)-ROUND(ROUND(F13*1.1*G13*(1+H13),10),2)-P13,"") | X13: =IF(AND(COUNT(C13:J13)=8,C13>0,D13>=0,E13>0,F13>=0,G13>0,G13=INT(G13),H13>=0,I13>=0,J13>0,J13=INT(J13),K13<>"",ISNUMBER(L13),L13>='00_审核入口'!$F$2,M13="已核实",N13="完整"),ROUND(I13+J13*S13,2),"") | Y13: =IF(AND(COUNT(C13:J13)=8,C13>0,D13>=0,E13>0,F13>=0,G13>0,G13=INT(G13),H13>=0,I13>=0,J13>0,J13=INT(J13),K13<>"",ISNUMBER(L13),L13>='00_审核入口'!$F$2,M13="已核实",N13="完整"),IF(S13>0,MAX(0,INT((500-I13)/S13)),""),"") | Z13: =IF(AND(COUNT(C13:J13)=8,C13>0,D13>=0,E13>0,F13>=0,G13>0,G13=INT(G13),H13>=0,I13>=0,J13>0,J13=INT(J13),K13<>"",ISNUMBER(L13),L13>='00_审核入口'!$F$2,M13="已核实",N13="完整"),IF(AND(T13>=15,U13>=0.2,W13>=0,X13<=500),"成本条件通过","成本条件不通过"),"待补证") -> 待补证
A14: C10 | B14: 衣物粘毛滚筒加替换芯 | M14: 待核实 | N14: =IF(COUNTIF('04_费用明细'!N167:N184,"完整")=18,"完整","待补证") -> 待补证 | O14: =IF(N14="完整",SUM('04_费用明细'!L167:L184),"") | P14: =IF(N14="完整",SUM('04_费用明细'!M167:M184),"") | Q14: =IF(AND(COUNT(C14:J14)=8,C14>0,D14>=0,E14>0,F14>=0,G14>0,G14=INT(G14),H14>=0,I14>=0,J14>0,J14=INT(J14),K14<>"",ISNUMBER(L14),L14>='00_审核入口'!$F$2,M14="已核实",N14="完整"),ROUND(ROUND((C14+D14)*E14,10),2),"") | R14: =IF(AND(COUNT(C14:J14)=8,C14>0,D14>=0,E14>0,F14>=0,G14>0,G14=INT(G14),H14>=0,I14>=0,J14>0,J14=INT(J14),K14<>"",ISNUMBER(L14),L14>='00_审核入口'!$F$2,M14="已核实",N14="完整"),ROUND(ROUND(F14*G14*(1+H14),10),2),"") | S14: =IF(AND(COUNT(C14:J14)=8,C14>0,D14>=0,E14>0,F14>=0,G14>0,G14=INT(G14),H14>=0,I14>=0,J14>0,J14=INT(J14),K14<>"",ISNUMBER(L14),L14>='00_审核入口'!$F$2,M14="已核实",N14="完整"),R14+O14,"") | T14: =IF(AND(COUNT(C14:J14)=8,C14>0,D14>=0,E14>0,F14>=0,G14>0,G14=INT(G14),H14>=0,I14>=0,J14>0,J14=INT(J14),K14<>"",ISNUMBER(L14),L14>='00_审核入口'!$F$2,M14="已核实",N14="完整"),Q14-S14,"") | U14: =IF(AND(COUNT(C14:J14)=8,C14>0,D14>=0,E14>0,F14>=0,G14>0,G14=INT(G14),H14>=0,I14>=0,J14>0,J14=INT(J14),K14<>"",ISNUMBER(L14),L14>='00_审核入口'!$F$2,M14="已核实",N14="完整"),IF(Q14>0,T14/Q14,""),"") | V14: =IF(AND(COUNT(C14:J14)=8,C14>0,D14>=0,E14>0,F14>=0,G14>0,G14=INT(G14),H14>=0,I14>=0,J14>0,J14=INT(J14),K14<>"",ISNUMBER(L14),L14>='00_审核入口'!$F$2,M14="已核实",N14="完整"),IF(Q14-O14-ROUNDUP(MAX(15,0.2*Q14),2)<0,"无非负可行采购价",ROUNDDOWN((Q14-O14-ROUNDUP(MAX(15,0.2*Q14),2)+0.005-0.0000000001)/(G14*(1+H14)),2)),"") | W14: =IF(AND(COUNT(C14:J14)=8,C14>0,D14>=0,E14>0,F14>=0,G14>0,G14=INT(G14),H14>=0,I14>=0,J14>0,J14=INT(J14),K14<>"",ISNUMBER(L14),L14>='00_审核入口'!$F$2,M14="已核实",N14="完整"),ROUND(ROUND((C14+D14)*E14*0.95,10),2)-ROUND(ROUND(F14*1.1*G14*(1+H14),10),2)-P14,"") | X14: =IF(AND(COUNT(C14:J14)=8,C14>0,D14>=0,E14>0,F14>=0,G14>0,G14=INT(G14),H14>=0,I14>=0,J14>0,J14=INT(J14),K14<>"",ISNUMBER(L14),L14>='00_审核入口'!$F$2,M14="已核实",N14="完整"),ROUND(I14+J14*S14,2),"") | Y14: =IF(AND(COUNT(C14:J14)=8,C14>0,D14>=0,E14>0,F14>=0,G14>0,G14=INT(G14),H14>=0,I14>=0,J14>0,J14=INT(J14),K14<>"",ISNUMBER(L14),L14>='00_审核入口'!$F$2,M14="已核实",N14="完整"),IF(S14>0,MAX(0,INT((500-I14)/S14)),""),"") | Z14: =IF(AND(COUNT(C14:J14)=8,C14>0,D14>=0,E14>0,F14>=0,G14>0,G14=INT(G14),H14>=0,I14>=0,J14>0,J14=INT(J14),K14<>"",ISNUMBER(L14),L14>='00_审核入口'!$F$2,M14="已核实",N14="完整"),IF(AND(T14>=15,U14>=0.2,W14>=0,X14<=500),"成本条件通过","成本条件不通过"),"待补证") -> 待补证
A15: C11 | B15: 硅胶排水口毛发过滤片 | M15: 待核实 | N15: =IF(COUNTIF('04_费用明细'!N185:N202,"完整")=18,"完整","待补证") -> 待补证 | O15: =IF(N15="完整",SUM('04_费用明细'!L185:L202),"") | P15: =IF(N15="完整",SUM('04_费用明细'!M185:M202),"") | Q15: =IF(AND(COUNT(C15:J15)=8,C15>0,D15>=0,E15>0,F15>=0,G15>0,G15=INT(G15),H15>=0,I15>=0,J15>0,J15=INT(J15),K15<>"",ISNUMBER(L15),L15>='00_审核入口'!$F$2,M15="已核实",N15="完整"),ROUND(ROUND((C15+D15)*E15,10),2),"") | R15: =IF(AND(COUNT(C15:J15)=8,C15>0,D15>=0,E15>0,F15>=0,G15>0,G15=INT(G15),H15>=0,I15>=0,J15>0,J15=INT(J15),K15<>"",ISNUMBER(L15),L15>='00_审核入口'!$F$2,M15="已核实",N15="完整"),ROUND(ROUND(F15*G15*(1+H15),10),2),"") | S15: =IF(AND(COUNT(C15:J15)=8,C15>0,D15>=0,E15>0,F15>=0,G15>0,G15=INT(G15),H15>=0,I15>=0,J15>0,J15=INT(J15),K15<>"",ISNUMBER(L15),L15>='00_审核入口'!$F$2,M15="已核实",N15="完整"),R15+O15,"") | T15: =IF(AND(COUNT(C15:J15)=8,C15>0,D15>=0,E15>0,F15>=0,G15>0,G15=INT(G15),H15>=0,I15>=0,J15>0,J15=INT(J15),K15<>"",ISNUMBER(L15),L15>='00_审核入口'!$F$2,M15="已核实",N15="完整"),Q15-S15,"") | U15: =IF(AND(COUNT(C15:J15)=8,C15>0,D15>=0,E15>0,F15>=0,G15>0,G15=INT(G15),H15>=0,I15>=0,J15>0,J15=INT(J15),K15<>"",ISNUMBER(L15),L15>='00_审核入口'!$F$2,M15="已核实",N15="完整"),IF(Q15>0,T15/Q15,""),"") | V15: =IF(AND(COUNT(C15:J15)=8,C15>0,D15>=0,E15>0,F15>=0,G15>0,G15=INT(G15),H15>=0,I15>=0,J15>0,J15=INT(J15),K15<>"",ISNUMBER(L15),L15>='00_审核入口'!$F$2,M15="已核实",N15="完整"),IF(Q15-O15-ROUNDUP(MAX(15,0.2*Q15),2)<0,"无非负可行采购价",ROUNDDOWN((Q15-O15-ROUNDUP(MAX(15,0.2*Q15),2)+0.005-0.0000000001)/(G15*(1+H15)),2)),"") | W15: =IF(AND(COUNT(C15:J15)=8,C15>0,D15>=0,E15>0,F15>=0,G15>0,G15=INT(G15),H15>=0,I15>=0,J15>0,J15=INT(J15),K15<>"",ISNUMBER(L15),L15>='00_审核入口'!$F$2,M15="已核实",N15="完整"),ROUND(ROUND((C15+D15)*E15*0.95,10),2)-ROUND(ROUND(F15*1.1*G15*(1+H15),10),2)-P15,"") | X15: =IF(AND(COUNT(C15:J15)=8,C15>0,D15>=0,E15>0,F15>=0,G15>0,G15=INT(G15),H15>=0,I15>=0,J15>0,J15=INT(J15),K15<>"",ISNUMBER(L15),L15>='00_审核入口'!$F$2,M15="已核实",N15="完整"),ROUND(I15+J15*S15,2),"") | Y15: =IF(AND(COUNT(C15:J15)=8,C15>0,D15>=0,E15>0,F15>=0,G15>0,G15=INT(G15),H15>=0,I15>=0,J15>0,J15=INT(J15),K15<>"",ISNUMBER(L15),L15>='00_审核入口'!$F$2,M15="已核实",N15="完整"),IF(S15>0,MAX(0,INT((500-I15)/S15)),""),"") | Z15: =IF(AND(COUNT(C15:J15)=8,C15>0,D15>=0,E15>0,F15>=0,G15>0,G15=INT(G15),H15>=0,I15>=0,J15>0,J15=INT(J15),K15<>"",ISNUMBER(L15),L15>='00_审核入口'!$F$2,M15="已核实",N15="完整"),IF(AND(T15>=15,U15>=0.2,W15>=0,X15<=500),"成本条件通过","成本条件不通过"),"待补证") -> 待补证
A16: C12 | B16: 挂式塑料袋收纳袋 | M16: 待核实 | N16: =IF(COUNTIF('04_费用明细'!N203:N220,"完整")=18,"完整","待补证") -> 待补证 | O16: =IF(N16="完整",SUM('04_费用明细'!L203:L220),"") | P16: =IF(N16="完整",SUM('04_费用明细'!M203:M220),"") | Q16: =IF(AND(COUNT(C16:J16)=8,C16>0,D16>=0,E16>0,F16>=0,G16>0,G16=INT(G16),H16>=0,I16>=0,J16>0,J16=INT(J16),K16<>"",ISNUMBER(L16),L16>='00_审核入口'!$F$2,M16="已核实",N16="完整"),ROUND(ROUND((C16+D16)*E16,10),2),"") | R16: =IF(AND(COUNT(C16:J16)=8,C16>0,D16>=0,E16>0,F16>=0,G16>0,G16=INT(G16),H16>=0,I16>=0,J16>0,J16=INT(J16),K16<>"",ISNUMBER(L16),L16>='00_审核入口'!$F$2,M16="已核实",N16="完整"),ROUND(ROUND(F16*G16*(1+H16),10),2),"") | S16: =IF(AND(COUNT(C16:J16)=8,C16>0,D16>=0,E16>0,F16>=0,G16>0,G16=INT(G16),H16>=0,I16>=0,J16>0,J16=INT(J16),K16<>"",ISNUMBER(L16),L16>='00_审核入口'!$F$2,M16="已核实",N16="完整"),R16+O16,"") | T16: =IF(AND(COUNT(C16:J16)=8,C16>0,D16>=0,E16>0,F16>=0,G16>0,G16=INT(G16),H16>=0,I16>=0,J16>0,J16=INT(J16),K16<>"",ISNUMBER(L16),L16>='00_审核入口'!$F$2,M16="已核实",N16="完整"),Q16-S16,"") | U16: =IF(AND(COUNT(C16:J16)=8,C16>0,D16>=0,E16>0,F16>=0,G16>0,G16=INT(G16),H16>=0,I16>=0,J16>0,J16=INT(J16),K16<>"",ISNUMBER(L16),L16>='00_审核入口'!$F$2,M16="已核实",N16="完整"),IF(Q16>0,T16/Q16,""),"") | V16: =IF(AND(COUNT(C16:J16)=8,C16>0,D16>=0,E16>0,F16>=0,G16>0,G16=INT(G16),H16>=0,I16>=0,J16>0,J16=INT(J16),K16<>"",ISNUMBER(L16),L16>='00_审核入口'!$F$2,M16="已核实",N16="完整"),IF(Q16-O16-ROUNDUP(MAX(15,0.2*Q16),2)<0,"无非负可行采购价",ROUNDDOWN((Q16-O16-ROUNDUP(MAX(15,0.2*Q16),2)+0.005-0.0000000001)/(G16*(1+H16)),2)),"") | W16: =IF(AND(COUNT(C16:J16)=8,C16>0,D16>=0,E16>0,F16>=0,G16>0,G16=INT(G16),H16>=0,I16>=0,J16>0,J16=INT(J16),K16<>"",ISNUMBER(L16),L16>='00_审核入口'!$F$2,M16="已核实",N16="完整"),ROUND(ROUND((C16+D16)*E16*0.95,10),2)-ROUND(ROUND(F16*1.1*G16*(1+H16),10),2)-P16,"") | X16: =IF(AND(COUNT(C16:J16)=8,C16>0,D16>=0,E16>0,F16>=0,G16>0,G16=INT(G16),H16>=0,I16>=0,J16>0,J16=INT(J16),K16<>"",ISNUMBER(L16),L16>='00_审核入口'!$F$2,M16="已核实",N16="完整"),ROUND(I16+J16*S16,2),"") | Y16: =IF(AND(COUNT(C16:J16)=8,C16>0,D16>=0,E16>0,F16>=0,G16>0,G16=INT(G16),H16>=0,I16>=0,J16>0,J16=INT(J16),K16<>"",ISNUMBER(L16),L16>='00_审核入口'!$F$2,M16="已核实",N16="完整"),IF(S16>0,MAX(0,INT((500-I16)/S16)),""),"") | Z16: =IF(AND(COUNT(C16:J16)=8,C16>0,D16>=0,E16>0,F16>=0,G16>0,G16=INT(G16),H16>=0,I16>=0,J16>0,J16=INT(J16),K16<>"",ISNUMBER(L16),L16>='00_审核入口'!$F$2,M16="已核实",N16="完整"),IF(AND(T16>=15,U16>=0.2,W16>=0,X16<=500),"成本条件通过","成本条件不通过"),"待补证") -> 待补证
A17: C13 | B17: 可重复使用粘扣理线带套装 | M17: 待核实 | N17: =IF(COUNTIF('04_费用明细'!N221:N238,"完整")=18,"完整","待补证") -> 待补证 | O17: =IF(N17="完整",SUM('04_费用明细'!L221:L238),"") | P17: =IF(N17="完整",SUM('04_费用明细'!M221:M238),"") | Q17: =IF(AND(COUNT(C17:J17)=8,C17>0,D17>=0,E17>0,F17>=0,G17>0,G17=INT(G17),H17>=0,I17>=0,J17>0,J17=INT(J17),K17<>"",ISNUMBER(L17),L17>='00_审核入口'!$F$2,M17="已核实",N17="完整"),ROUND(ROUND((C17+D17)*E17,10),2),"") | R17: =IF(AND(COUNT(C17:J17)=8,C17>0,D17>=0,E17>0,F17>=0,G17>0,G17=INT(G17),H17>=0,I17>=0,J17>0,J17=INT(J17),K17<>"",ISNUMBER(L17),L17>='00_审核入口'!$F$2,M17="已核实",N17="完整"),ROUND(ROUND(F17*G17*(1+H17),10),2),"") | S17: =IF(AND(COUNT(C17:J17)=8,C17>0,D17>=0,E17>0,F17>=0,G17>0,G17=INT(G17),H17>=0,I17>=0,J17>0,J17=INT(J17),K17<>"",ISNUMBER(L17),L17>='00_审核入口'!$F$2,M17="已核实",N17="完整"),R17+O17,"") | T17: =IF(AND(COUNT(C17:J17)=8,C17>0,D17>=0,E17>0,F17>=0,G17>0,G17=INT(G17),H17>=0,I17>=0,J17>0,J17=INT(J17),K17<>"",ISNUMBER(L17),L17>='00_审核入口'!$F$2,M17="已核实",N17="完整"),Q17-S17,"") | U17: =IF(AND(COUNT(C17:J17)=8,C17>0,D17>=0,E17>0,F17>=0,G17>0,G17=INT(G17),H17>=0,I17>=0,J17>0,J17=INT(J17),K17<>"",ISNUMBER(L17),L17>='00_审核入口'!$F$2,M17="已核实",N17="完整"),IF(Q17>0,T17/Q17,""),"") | V17: =IF(AND(COUNT(C17:J17)=8,C17>0,D17>=0,E17>0,F17>=0,G17>0,G17=INT(G17),H17>=0,I17>=0,J17>0,J17=INT(J17),K17<>"",ISNUMBER(L17),L17>='00_审核入口'!$F$2,M17="已核实",N17="完整"),IF(Q17-O17-ROUNDUP(MAX(15,0.2*Q17),2)<0,"无非负可行采购价",ROUNDDOWN((Q17-O17-ROUNDUP(MAX(15,0.2*Q17),2)+0.005-0.0000000001)/(G17*(1+H17)),2)),"") | W17: =IF(AND(COUNT(C17:J17)=8,C17>0,D17>=0,E17>0,F17>=0,G17>0,G17=INT(G17),H17>=0,I17>=0,J17>0,J17=INT(J17),K17<>"",ISNUMBER(L17),L17>='00_审核入口'!$F$2,M17="已核实",N17="完整"),ROUND(ROUND((C17+D17)*E17*0.95,10),2)-ROUND(ROUND(F17*1.1*G17*(1+H17),10),2)-P17,"") | X17: =IF(AND(COUNT(C17:J17)=8,C17>0,D17>=0,E17>0,F17>=0,G17>0,G17=INT(G17),H17>=0,I17>=0,J17>0,J17=INT(J17),K17<>"",ISNUMBER(L17),L17>='00_审核入口'!$F$2,M17="已核实",N17="完整"),ROUND(I17+J17*S17,2),"") | Y17: =IF(AND(COUNT(C17:J17)=8,C17>0,D17>=0,E17>0,F17>=0,G17>0,G17=INT(G17),H17>=0,I17>=0,J17>0,J17=INT(J17),K17<>"",ISNUMBER(L17),L17>='00_审核入口'!$F$2,M17="已核实",N17="完整"),IF(S17>0,MAX(0,INT((500-I17)/S17)),""),"") | Z17: =IF(AND(COUNT(C17:J17)=8,C17>0,D17>=0,E17>0,F17>=0,G17>0,G17=INT(G17),H17>=0,I17>=0,J17>0,J17=INT(J17),K17<>"",ISNUMBER(L17),L17>='00_审核入口'!$F$2,M17="已核实",N17="完整"),IF(AND(T17>=15,U17>=0.2,W17>=0,X17<=500),"成本条件通过","成本条件不通过"),"待补证") -> 待补证
A18: C14 | B18: 网眼拉链旅行收纳包 | M18: 待核实 | N18: =IF(COUNTIF('04_费用明细'!N239:N256,"完整")=18,"完整","待补证") -> 待补证 | O18: =IF(N18="完整",SUM('04_费用明细'!L239:L256),"") | P18: =IF(N18="完整",SUM('04_费用明细'!M239:M256),"") | Q18: =IF(AND(COUNT(C18:J18)=8,C18>0,D18>=0,E18>0,F18>=0,G18>0,G18=INT(G18),H18>=0,I18>=0,J18>0,J18=INT(J18),K18<>"",ISNUMBER(L18),L18>='00_审核入口'!$F$2,M18="已核实",N18="完整"),ROUND(ROUND((C18+D18)*E18,10),2),"") | R18: =IF(AND(COUNT(C18:J18)=8,C18>0,D18>=0,E18>0,F18>=0,G18>0,G18=INT(G18),H18>=0,I18>=0,J18>0,J18=INT(J18),K18<>"",ISNUMBER(L18),L18>='00_审核入口'!$F$2,M18="已核实",N18="完整"),ROUND(ROUND(F18*G18*(1+H18),10),2),"") | S18: =IF(AND(COUNT(C18:J18)=8,C18>0,D18>=0,E18>0,F18>=0,G18>0,G18=INT(G18),H18>=0,I18>=0,J18>0,J18=INT(J18),K18<>"",ISNUMBER(L18),L18>='00_审核入口'!$F$2,M18="已核实",N18="完整"),R18+O18,"") | T18: =IF(AND(COUNT(C18:J18)=8,C18>0,D18>=0,E18>0,F18>=0,G18>0,G18=INT(G18),H18>=0,I18>=0,J18>0,J18=INT(J18),K18<>"",ISNUMBER(L18),L18>='00_审核入口'!$F$2,M18="已核实",N18="完整"),Q18-S18,"") | U18: =IF(AND(COUNT(C18:J18)=8,C18>0,D18>=0,E18>0,F18>=0,G18>0,G18=INT(G18),H18>=0,I18>=0,J18>0,J18=INT(J18),K18<>"",ISNUMBER(L18),L18>='00_审核入口'!$F$2,M18="已核实",N18="完整"),IF(Q18>0,T18/Q18,""),"") | V18: =IF(AND(COUNT(C18:J18)=8,C18>0,D18>=0,E18>0,F18>=0,G18>0,G18=INT(G18),H18>=0,I18>=0,J18>0,J18=INT(J18),K18<>"",ISNUMBER(L18),L18>='00_审核入口'!$F$2,M18="已核实",N18="完整"),IF(Q18-O18-ROUNDUP(MAX(15,0.2*Q18),2)<0,"无非负可行采购价",ROUNDDOWN((Q18-O18-ROUNDUP(MAX(15,0.2*Q18),2)+0.005-0.0000000001)/(G18*(1+H18)),2)),"") | W18: =IF(AND(COUNT(C18:J18)=8,C18>0,D18>=0,E18>0,F18>=0,G18>0,G18=INT(G18),H18>=0,I18>=0,J18>0,J18=INT(J18),K18<>"",ISNUMBER(L18),L18>='00_审核入口'!$F$2,M18="已核实",N18="完整"),ROUND(ROUND((C18+D18)*E18*0.95,10),2)-ROUND(ROUND(F18*1.1*G18*(1+H18),10),2)-P18,"") | X18: =IF(AND(COUNT(C18:J18)=8,C18>0,D18>=0,E18>0,F18>=0,G18>0,G18=INT(G18),H18>=0,I18>=0,J18>0,J18=INT(J18),K18<>"",ISNUMBER(L18),L18>='00_审核入口'!$F$2,M18="已核实",N18="完整"),ROUND(I18+J18*S18,2),"") | Y18: =IF(AND(COUNT(C18:J18)=8,C18>0,D18>=0,E18>0,F18>=0,G18>0,G18=INT(G18),H18>=0,I18>=0,J18>0,J18=INT(J18),K18<>"",ISNUMBER(L18),L18>='00_审核入口'!$F$2,M18="已核实",N18="完整"),IF(S18>0,MAX(0,INT((500-I18)/S18)),""),"") | Z18: =IF(AND(COUNT(C18:J18)=8,C18>0,D18>=0,E18>0,F18>=0,G18>0,G18=INT(G18),H18>=0,I18>=0,J18>0,J18=INT(J18),K18<>"",ISNUMBER(L18),L18>='00_审核入口'!$F$2,M18="已核实",N18="完整"),IF(AND(T18>=15,U18>=0.2,W18>=0,X18<=500),"成本条件通过","成本条件不通过"),"待补证") -> 待补证
A19: C15 | B19: 五合一可折叠裤架 | M19: 待核实 | N19: =IF(COUNTIF('04_费用明细'!N257:N274,"完整")=18,"完整","待补证") -> 待补证 | O19: =IF(N19="完整",SUM('04_费用明细'!L257:L274),"") | P19: =IF(N19="完整",SUM('04_费用明细'!M257:M274),"") | Q19: =IF(AND(COUNT(C19:J19)=8,C19>0,D19>=0,E19>0,F19>=0,G19>0,G19=INT(G19),H19>=0,I19>=0,J19>0,J19=INT(J19),K19<>"",ISNUMBER(L19),L19>='00_审核入口'!$F$2,M19="已核实",N19="完整"),ROUND(ROUND((C19+D19)*E19,10),2),"") | R19: =IF(AND(COUNT(C19:J19)=8,C19>0,D19>=0,E19>0,F19>=0,G19>0,G19=INT(G19),H19>=0,I19>=0,J19>0,J19=INT(J19),K19<>"",ISNUMBER(L19),L19>='00_审核入口'!$F$2,M19="已核实",N19="完整"),ROUND(ROUND(F19*G19*(1+H19),10),2),"") | S19: =IF(AND(COUNT(C19:J19)=8,C19>0,D19>=0,E19>0,F19>=0,G19>0,G19=INT(G19),H19>=0,I19>=0,J19>0,J19=INT(J19),K19<>"",ISNUMBER(L19),L19>='00_审核入口'!$F$2,M19="已核实",N19="完整"),R19+O19,"") | T19: =IF(AND(COUNT(C19:J19)=8,C19>0,D19>=0,E19>0,F19>=0,G19>0,G19=INT(G19),H19>=0,I19>=0,J19>0,J19=INT(J19),K19<>"",ISNUMBER(L19),L19>='00_审核入口'!$F$2,M19="已核实",N19="完整"),Q19-S19,"") | U19: =IF(AND(COUNT(C19:J19)=8,C19>0,D19>=0,E19>0,F19>=0,G19>0,G19=INT(G19),H19>=0,I19>=0,J19>0,J19=INT(J19),K19<>"",ISNUMBER(L19),L19>='00_审核入口'!$F$2,M19="已核实",N19="完整"),IF(Q19>0,T19/Q19,""),"") | V19: =IF(AND(COUNT(C19:J19)=8,C19>0,D19>=0,E19>0,F19>=0,G19>0,G19=INT(G19),H19>=0,I19>=0,J19>0,J19=INT(J19),K19<>"",ISNUMBER(L19),L19>='00_审核入口'!$F$2,M19="已核实",N19="完整"),IF(Q19-O19-ROUNDUP(MAX(15,0.2*Q19),2)<0,"无非负可行采购价",ROUNDDOWN((Q19-O19-ROUNDUP(MAX(15,0.2*Q19),2)+0.005-0.0000000001)/(G19*(1+H19)),2)),"") | W19: =IF(AND(COUNT(C19:J19)=8,C19>0,D19>=0,E19>0,F19>=0,G19>0,G19=INT(G19),H19>=0,I19>=0,J19>0,J19=INT(J19),K19<>"",ISNUMBER(L19),L19>='00_审核入口'!$F$2,M19="已核实",N19="完整"),ROUND(ROUND((C19+D19)*E19*0.95,10),2)-ROUND(ROUND(F19*1.1*G19*(1+H19),10),2)-P19,"") | X19: =IF(AND(COUNT(C19:J19)=8,C19>0,D19>=0,E19>0,F19>=0,G19>0,G19=INT(G19),H19>=0,I19>=0,J19>0,J19=INT(J19),K19<>"",ISNUMBER(L19),L19>='00_审核入口'!$F$2,M19="已核实",N19="完整"),ROUND(I19+J19*S19,2),"") | Y19: =IF(AND(COUNT(C19:J19)=8,C19>0,D19>=0,E19>0,F19>=0,G19>0,G19=INT(G19),H19>=0,I19>=0,J19>0,J19=INT(J19),K19<>"",ISNUMBER(L19),L19>='00_审核入口'!$F$2,M19="已核实",N19="完整"),IF(S19>0,MAX(0,INT((500-I19)/S19)),""),"") | Z19: =IF(AND(COUNT(C19:J19)=8,C19>0,D19>=0,E19>0,F19>=0,G19>0,G19=INT(G19),H19>=0,I19>=0,J19>0,J19=INT(J19),K19<>"",ISNUMBER(L19),L19>='00_审核入口'!$F$2,M19="已核实",N19="完整"),IF(AND(T19>=15,U19>=0.2,W19>=0,X19<=500),"成本条件通过","成本条件不通过"),"待补证") -> 待补证
A20: C16 | B20: 双层线材旅行收纳包 | M20: 待核实 | N20: =IF(COUNTIF('04_费用明细'!N275:N292,"完整")=18,"完整","待补证") -> 待补证 | O20: =IF(N20="完整",SUM('04_费用明细'!L275:L292),"") | P20: =IF(N20="完整",SUM('04_费用明细'!M275:M292),"") | Q20: =IF(AND(COUNT(C20:J20)=8,C20>0,D20>=0,E20>0,F20>=0,G20>0,G20=INT(G20),H20>=0,I20>=0,J20>0,J20=INT(J20),K20<>"",ISNUMBER(L20),L20>='00_审核入口'!$F$2,M20="已核实",N20="完整"),ROUND(ROUND((C20+D20)*E20,10),2),"") | R20: =IF(AND(COUNT(C20:J20)=8,C20>0,D20>=0,E20>0,F20>=0,G20>0,G20=INT(G20),H20>=0,I20>=0,J20>0,J20=INT(J20),K20<>"",ISNUMBER(L20),L20>='00_审核入口'!$F$2,M20="已核实",N20="完整"),ROUND(ROUND(F20*G20*(1+H20),10),2),"") | S20: =IF(AND(COUNT(C20:J20)=8,C20>0,D20>=0,E20>0,F20>=0,G20>0,G20=INT(G20),H20>=0,I20>=0,J20>0,J20=INT(J20),K20<>"",ISNUMBER(L20),L20>='00_审核入口'!$F$2,M20="已核实",N20="完整"),R20+O20,"") | T20: =IF(AND(COUNT(C20:J20)=8,C20>0,D20>=0,E20>0,F20>=0,G20>0,G20=INT(G20),H20>=0,I20>=0,J20>0,J20=INT(J20),K20<>"",ISNUMBER(L20),L20>='00_审核入口'!$F$2,M20="已核实",N20="完整"),Q20-S20,"") | U20: =IF(AND(COUNT(C20:J20)=8,C20>0,D20>=0,E20>0,F20>=0,G20>0,G20=INT(G20),H20>=0,I20>=0,J20>0,J20=INT(J20),K20<>"",ISNUMBER(L20),L20>='00_审核入口'!$F$2,M20="已核实",N20="完整"),IF(Q20>0,T20/Q20,""),"") | V20: =IF(AND(COUNT(C20:J20)=8,C20>0,D20>=0,E20>0,F20>=0,G20>0,G20=INT(G20),H20>=0,I20>=0,J20>0,J20=INT(J20),K20<>"",ISNUMBER(L20),L20>='00_审核入口'!$F$2,M20="已核实",N20="完整"),IF(Q20-O20-ROUNDUP(MAX(15,0.2*Q20),2)<0,"无非负可行采购价",ROUNDDOWN((Q20-O20-ROUNDUP(MAX(15,0.2*Q20),2)+0.005-0.0000000001)/(G20*(1+H20)),2)),"") | W20: =IF(AND(COUNT(C20:J20)=8,C20>0,D20>=0,E20>0,F20>=0,G20>0,G20=INT(G20),H20>=0,I20>=0,J20>0,J20=INT(J20),K20<>"",ISNUMBER(L20),L20>='00_审核入口'!$F$2,M20="已核实",N20="完整"),ROUND(ROUND((C20+D20)*E20*0.95,10),2)-ROUND(ROUND(F20*1.1*G20*(1+H20),10),2)-P20,"") | X20: =IF(AND(COUNT(C20:J20)=8,C20>0,D20>=0,E20>0,F20>=0,G20>0,G20=INT(G20),H20>=0,I20>=0,J20>0,J20=INT(J20),K20<>"",ISNUMBER(L20),L20>='00_审核入口'!$F$2,M20="已核实",N20="完整"),ROUND(I20+J20*S20,2),"") | Y20: =IF(AND(COUNT(C20:J20)=8,C20>0,D20>=0,E20>0,F20>=0,G20>0,G20=INT(G20),H20>=0,I20>=0,J20>0,J20=INT(J20),K20<>"",ISNUMBER(L20),L20>='00_审核入口'!$F$2,M20="已核实",N20="完整"),IF(S20>0,MAX(0,INT((500-I20)/S20)),""),"") | Z20: =IF(AND(COUNT(C20:J20)=8,C20>0,D20>=0,E20>0,F20>=0,G20>0,G20=INT(G20),H20>=0,I20>=0,J20>0,J20=INT(J20),K20<>"",ISNUMBER(L20),L20>='00_审核入口'!$F$2,M20="已核实",N20="完整"),IF(AND(T20>=15,U20>=0.2,W20>=0,X20<=500),"成本条件通过","成本条件不通过"),"待补证") -> 待补证
A21: C17 | B21: 便携首饰分格收纳盒 | M21: 待核实 | N21: =IF(COUNTIF('04_费用明细'!N293:N310,"完整")=18,"完整","待补证") -> 待补证 | O21: =IF(N21="完整",SUM('04_费用明细'!L293:L310),"") | P21: =IF(N21="完整",SUM('04_费用明细'!M293:M310),"") | Q21: =IF(AND(COUNT(C21:J21)=8,C21>0,D21>=0,E21>0,F21>=0,G21>0,G21=INT(G21),H21>=0,I21>=0,J21>0,J21=INT(J21),K21<>"",ISNUMBER(L21),L21>='00_审核入口'!$F$2,M21="已核实",N21="完整"),ROUND(ROUND((C21+D21)*E21,10),2),"") | R21: =IF(AND(COUNT(C21:J21)=8,C21>0,D21>=0,E21>0,F21>=0,G21>0,G21=INT(G21),H21>=0,I21>=0,J21>0,J21=INT(J21),K21<>"",ISNUMBER(L21),L21>='00_审核入口'!$F$2,M21="已核实",N21="完整"),ROUND(ROUND(F21*G21*(1+H21),10),2),"") | S21: =IF(AND(COUNT(C21:J21)=8,C21>0,D21>=0,E21>0,F21>=0,G21>0,G21=INT(G21),H21>=0,I21>=0,J21>0,J21=INT(J21),K21<>"",ISNUMBER(L21),L21>='00_审核入口'!$F$2,M21="已核实",N21="完整"),R21+O21,"") | T21: =IF(AND(COUNT(C21:J21)=8,C21>0,D21>=0,E21>0,F21>=0,G21>0,G21=INT(G21),H21>=0,I21>=0,J21>0,J21=INT(J21),K21<>"",ISNUMBER(L21),L21>='00_审核入口'!$F$2,M21="已核实",N21="完整"),Q21-S21,"") | U21: =IF(AND(COUNT(C21:J21)=8,C21>0,D21>=0,E21>0,F21>=0,G21>0,G21=INT(G21),H21>=0,I21>=0,J21>0,J21=INT(J21),K21<>"",ISNUMBER(L21),L21>='00_审核入口'!$F$2,M21="已核实",N21="完整"),IF(Q21>0,T21/Q21,""),"") | V21: =IF(AND(COUNT(C21:J21)=8,C21>0,D21>=0,E21>0,F21>=0,G21>0,G21=INT(G21),H21>=0,I21>=0,J21>0,J21=INT(J21),K21<>"",ISNUMBER(L21),L21>='00_审核入口'!$F$2,M21="已核实",N21="完整"),IF(Q21-O21-ROUNDUP(MAX(15,0.2*Q21),2)<0,"无非负可行采购价",ROUNDDOWN((Q21-O21-ROUNDUP(MAX(15,0.2*Q21),2)+0.005-0.0000000001)/(G21*(1+H21)),2)),"") | W21: =IF(AND(COUNT(C21:J21)=8,C21>0,D21>=0,E21>0,F21>=0,G21>0,G21=INT(G21),H21>=0,I21>=0,J21>0,J21=INT(J21),K21<>"",ISNUMBER(L21),L21>='00_审核入口'!$F$2,M21="已核实",N21="完整"),ROUND(ROUND((C21+D21)*E21*0.95,10),2)-ROUND(ROUND(F21*1.1*G21*(1+H21),10),2)-P21,"") | X21: =IF(AND(COUNT(C21:J21)=8,C21>0,D21>=0,E21>0,F21>=0,G21>0,G21=INT(G21),H21>=0,I21>=0,J21>0,J21=INT(J21),K21<>"",ISNUMBER(L21),L21>='00_审核入口'!$F$2,M21="已核实",N21="完整"),ROUND(I21+J21*S21,2),"") | Y21: =IF(AND(COUNT(C21:J21)=8,C21>0,D21>=0,E21>0,F21>=0,G21>0,G21=INT(G21),H21>=0,I21>=0,J21>0,J21=INT(J21),K21<>"",ISNUMBER(L21),L21>='00_审核入口'!$F$2,M21="已核实",N21="完整"),IF(S21>0,MAX(0,INT((500-I21)/S21)),""),"") | Z21: =IF(AND(COUNT(C21:J21)=8,C21>0,D21>=0,E21>0,F21>=0,G21>0,G21=INT(G21),H21>=0,I21>=0,J21>0,J21=INT(J21),K21<>"",ISNUMBER(L21),L21>='00_审核入口'!$F$2,M21="已核实",N21="完整"),IF(AND(T21>=15,U21>=0.2,W21>=0,X21<=500),"成本条件通过","成本条件不通过"),"待补证") -> 待补证
A22: C18 | B22: 门背免打孔挂钩架 | M22: 待核实 | N22: =IF(COUNTIF('04_费用明细'!N311:N328,"完整")=18,"完整","待补证") -> 待补证 | O22: =IF(N22="完整",SUM('04_费用明细'!L311:L328),"") | P22: =IF(N22="完整",SUM('04_费用明细'!M311:M328),"") | Q22: =IF(AND(COUNT(C22:J22)=8,C22>0,D22>=0,E22>0,F22>=0,G22>0,G22=INT(G22),H22>=0,I22>=0,J22>0,J22=INT(J22),K22<>"",ISNUMBER(L22),L22>='00_审核入口'!$F$2,M22="已核实",N22="完整"),ROUND(ROUND((C22+D22)*E22,10),2),"") | R22: =IF(AND(COUNT(C22:J22)=8,C22>0,D22>=0,E22>0,F22>=0,G22>0,G22=INT(G22),H22>=0,I22>=0,J22>0,J22=INT(J22),K22<>"",ISNUMBER(L22),L22>='00_审核入口'!$F$2,M22="已核实",N22="完整"),ROUND(ROUND(F22*G22*(1+H22),10),2),"") | S22: =IF(AND(COUNT(C22:J22)=8,C22>0,D22>=0,E22>0,F22>=0,G22>0,G22=INT(G22),H22>=0,I22>=0,J22>0,J22=INT(J22),K22<>"",ISNUMBER(L22),L22>='00_审核入口'!$F$2,M22="已核实",N22="完整"),R22+O22,"") | T22: =IF(AND(COUNT(C22:J22)=8,C22>0,D22>=0,E22>0,F22>=0,G22>0,G22=INT(G22),H22>=0,I22>=0,J22>0,J22=INT(J22),K22<>"",ISNUMBER(L22),L22>='00_审核入口'!$F$2,M22="已核实",N22="完整"),Q22-S22,"") | U22: =IF(AND(COUNT(C22:J22)=8,C22>0,D22>=0,E22>0,F22>=0,G22>0,G22=INT(G22),H22>=0,I22>=0,J22>0,J22=INT(J22),K22<>"",ISNUMBER(L22),L22>='00_审核入口'!$F$2,M22="已核实",N22="完整"),IF(Q22>0,T22/Q22,""),"") | V22: =IF(AND(COUNT(C22:J22)=8,C22>0,D22>=0,E22>0,F22>=0,G22>0,G22=INT(G22),H22>=0,I22>=0,J22>0,J22=INT(J22),K22<>"",ISNUMBER(L22),L22>='00_审核入口'!$F$2,M22="已核实",N22="完整"),IF(Q22-O22-ROUNDUP(MAX(15,0.2*Q22),2)<0,"无非负可行采购价",ROUNDDOWN((Q22-O22-ROUNDUP(MAX(15,0.2*Q22),2)+0.005-0.0000000001)/(G22*(1+H22)),2)),"") | W22: =IF(AND(COUNT(C22:J22)=8,C22>0,D22>=0,E22>0,F22>=0,G22>0,G22=INT(G22),H22>=0,I22>=0,J22>0,J22=INT(J22),K22<>"",ISNUMBER(L22),L22>='00_审核入口'!$F$2,M22="已核实",N22="完整"),ROUND(ROUND((C22+D22)*E22*0.95,10),2)-ROUND(ROUND(F22*1.1*G22*(1+H22),10),2)-P22,"") | X22: =IF(AND(COUNT(C22:J22)=8,C22>0,D22>=0,E22>0,F22>=0,G22>0,G22=INT(G22),H22>=0,I22>=0,J22>0,J22=INT(J22),K22<>"",ISNUMBER(L22),L22>='00_审核入口'!$F$2,M22="已核实",N22="完整"),ROUND(I22+J22*S22,2),"") | Y22: =IF(AND(COUNT(C22:J22)=8,C22>0,D22>=0,E22>0,F22>=0,G22>0,G22=INT(G22),H22>=0,I22>=0,J22>0,J22=INT(J22),K22<>"",ISNUMBER(L22),L22>='00_审核入口'!$F$2,M22="已核实",N22="完整"),IF(S22>0,MAX(0,INT((500-I22)/S22)),""),"") | Z22: =IF(AND(COUNT(C22:J22)=8,C22>0,D22>=0,E22>0,F22>=0,G22>0,G22=INT(G22),H22>=0,I22>=0,J22>0,J22=INT(J22),K22<>"",ISNUMBER(L22),L22>='00_审核入口'!$F$2,M22="已核实",N22="完整"),IF(AND(T22>=15,U22>=0.2,W22>=0,X22<=500),"成本条件通过","成本条件不通过"),"待补证") -> 待补证
A23: C19 | B23: 十夹式小件晾晒衣架 | M23: 待核实 | N23: =IF(COUNTIF('04_费用明细'!N329:N346,"完整")=18,"完整","待补证") -> 待补证 | O23: =IF(N23="完整",SUM('04_费用明细'!L329:L346),"") | P23: =IF(N23="完整",SUM('04_费用明细'!M329:M346),"") | Q23: =IF(AND(COUNT(C23:J23)=8,C23>0,D23>=0,E23>0,F23>=0,G23>0,G23=INT(G23),H23>=0,I23>=0,J23>0,J23=INT(J23),K23<>"",ISNUMBER(L23),L23>='00_审核入口'!$F$2,M23="已核实",N23="完整"),ROUND(ROUND((C23+D23)*E23,10),2),"") | R23: =IF(AND(COUNT(C23:J23)=8,C23>0,D23>=0,E23>0,F23>=0,G23>0,G23=INT(G23),H23>=0,I23>=0,J23>0,J23=INT(J23),K23<>"",ISNUMBER(L23),L23>='00_审核入口'!$F$2,M23="已核实",N23="完整"),ROUND(ROUND(F23*G23*(1+H23),10),2),"") | S23: =IF(AND(COUNT(C23:J23)=8,C23>0,D23>=0,E23>0,F23>=0,G23>0,G23=INT(G23),H23>=0,I23>=0,J23>0,J23=INT(J23),K23<>"",ISNUMBER(L23),L23>='00_审核入口'!$F$2,M23="已核实",N23="完整"),R23+O23,"") | T23: =IF(AND(COUNT(C23:J23)=8,C23>0,D23>=0,E23>0,F23>=0,G23>0,G23=INT(G23),H23>=0,I23>=0,J23>0,J23=INT(J23),K23<>"",ISNUMBER(L23),L23>='00_审核入口'!$F$2,M23="已核实",N23="完整"),Q23-S23,"") | U23: =IF(AND(COUNT(C23:J23)=8,C23>0,D23>=0,E23>0,F23>=0,G23>0,G23=INT(G23),H23>=0,I23>=0,J23>0,J23=INT(J23),K23<>"",ISNUMBER(L23),L23>='00_审核入口'!$F$2,M23="已核实",N23="完整"),IF(Q23>0,T23/Q23,""),"") | V23: =IF(AND(COUNT(C23:J23)=8,C23>0,D23>=0,E23>0,F23>=0,G23>0,G23=INT(G23),H23>=0,I23>=0,J23>0,J23=INT(J23),K23<>"",ISNUMBER(L23),L23>='00_审核入口'!$F$2,M23="已核实",N23="完整"),IF(Q23-O23-ROUNDUP(MAX(15,0.2*Q23),2)<0,"无非负可行采购价",ROUNDDOWN((Q23-O23-ROUNDUP(MAX(15,0.2*Q23),2)+0.005-0.0000000001)/(G23*(1+H23)),2)),"") | W23: =IF(AND(COUNT(C23:J23)=8,C23>0,D23>=0,E23>0,F23>=0,G23>0,G23=INT(G23),H23>=0,I23>=0,J23>0,J23=INT(J23),K23<>"",ISNUMBER(L23),L23>='00_审核入口'!$F$2,M23="已核实",N23="完整"),ROUND(ROUND((C23+D23)*E23*0.95,10),2)-ROUND(ROUND(F23*1.1*G23*(1+H23),10),2)-P23,"") | X23: =IF(AND(COUNT(C23:J23)=8,C23>0,D23>=0,E23>0,F23>=0,G23>0,G23=INT(G23),H23>=0,I23>=0,J23>0,J23=INT(J23),K23<>"",ISNUMBER(L23),L23>='00_审核入口'!$F$2,M23="已核实",N23="完整"),ROUND(I23+J23*S23,2),"") | Y23: =IF(AND(COUNT(C23:J23)=8,C23>0,D23>=0,E23>0,F23>=0,G23>0,G23=INT(G23),H23>=0,I23>=0,J23>0,J23=INT(J23),K23<>"",ISNUMBER(L23),L23>='00_审核入口'!$F$2,M23="已核实",N23="完整"),IF(S23>0,MAX(0,INT((500-I23)/S23)),""),"") | Z23: =IF(AND(COUNT(C23:J23)=8,C23>0,D23>=0,E23>0,F23>=0,G23>0,G23=INT(G23),H23>=0,I23>=0,J23>0,J23=INT(J23),K23<>"",ISNUMBER(L23),L23>='00_审核入口'!$F$2,M23="已核实",N23="完整"),IF(AND(T23>=15,U23>=0.2,W23>=0,X23<=500),"成本条件通过","成本条件不通过"),"待补证") -> 待补证
